Workbook
Name V: _xludf.LAMBDA(loc, input_param, INDEX(in_loc!$D:$AD, MATCH(input_param, in_loc!$A:$A, 0), MATCH(loc, in_loc!$D$1:$AD$1, 0)))

Sheet summary
A1: =in_loc!A1 -> 0 | B1: =in_loc!D1 -> n_2 | C1: =in_loc!E1 -> n_25 | D1: =in_loc!F1 -> n_10 | E1: =in_loc!G1 -> b_2 | F1: =in_loc!H1 -> b_25 | G1: =in_loc!I1 -> b_10 | H1: =in_loc!J1 -> m_2 | I1: =in_loc!K1 -> m_25 | J1: =in_loc!L1 -> m_10 | K1: =B1&"_pes" -> n_2_pes | L1: =C1&"_pes" -> n_25_pes | M1: =D1&"_pes" -> n_10_pes | N1: =E1&"_pes" -> b_2_pes | O1: =F1&"_pes" -> b_25_pes | P1: =G1&"_pes" -> b_10_pes | Q1: =H1&"_pes" -> m_2_pes | R1: =I1&"_pes" -> m_25_pes | S1: =J1&"_pes" -> m_10_pes | T1: =B1&"_opt" -> n_2_opt | U1: =C1&"_opt" -> n_25_opt | V1: =D1&"_opt" -> n_10_opt | W1: =E1&"_opt" -> b_2_opt | X1: =F1&"_opt" -> b_25_opt | Y1: =G1&"_opt" -> b_10_opt | Z1: =H1&"_opt" -> m_2_opt | AA1: =I1&"_opt" -> m_25_opt | AB1: =J1&"_opt" -> m_10_opt
A2: CAPEX (€) | B2: =out_loc!D$23 -> 3895514.9 | C2: =out_loc!E$23 -> 18215574 | D2: =out_loc!F$23 -> 13368498 | E2: =out_loc!G$23 -> 2610396.9 | F2: =out_loc!H$23 -> 12850985 | G2: =out_loc!I$23 -> 9697751.9 | H2: =out_loc!J$23 -> 2561106.1 | I2: =out_loc!K$23 -> 12591531 | ... AB2: =out_loc!AD$23 -> 9001158.4
A3: OPEX (€) | B3: =out_loc!D$25+out_loc!D$29 -> 515087.46 | C3: =out_loc!E$25+out_loc!E$29 -> 2575437.3 | D3: =out_loc!F$25+out_loc!F$29 -> 1794221.3 | E3: =out_loc!G$25+out_loc!G$29 -> 412069.97 | F3: =out_loc!H$25+out_loc!H$29 -> 2060349.8 | G3: =out_loc!I$25+out_loc!I$29 -> 1435377.1 | H3: =out_loc!J$25+out_loc!J$29 -> 257543.73 | I3: =out_loc!K$25+out_loc!K$29 -> 1287718.7 | ... AB3: =out_loc!AD$25+out_loc!AD$29 -> 897198.23
A4: Revenue (€) | B4: =out_loc!D$30 -> 2866869.6 | C4: =out_loc!E$30 -> 14334348 | D4: =out_loc!F$30 -> 13115756 | E4: =out_loc!G$30 -> 3026445.1 | F4: =out_loc!H$30 -> 15132225 | G4: =out_loc!I$30 -> 13952094 | H4: =out_loc!J$30 -> 4317061.9 | I4: =out_loc!K$30 -> 21585310 | ... AB4: =out_loc!AD$30 -> 20793882
A5: LCOE (€) | B5: =out_loc!D26 -> 0.1846168 | C5: =out_loc!E26 -> 0.17405196 | D5: =out_loc!F26 -> 0.13872828 | E5: =out_loc!G26 -> 0.11984226 | F5: =out_loc!H26 -> 0.11824831 | G5: =out_loc!I26 -> 0.095754475 | H5: =out_loc!J26 -> 0.078349116 | I5: =out_loc!K26 -> 0.077159417 | ... AB5: =out_loc!AD26 -> 0.054837797
A6: NPV (€) | B6: =out_loc!D31 -> -1734179.8 | C6: =out_loc!E31 -> -7070346.4 | D6: =out_loc!F31 -> -2856592.4 | E6: =out_loc!G31 -> -138507.13 | F6: =out_loc!H31 -> -361234.42 | G6: =out_loc!I31 -> 2158881.8 | H6: =out_loc!J31 -> 1360693.1 | I6: =out_loc!K31 -> 7127787.8 | ... AB6: =out_loc!AD31 -> 10284081
A7: ROI (%) | B7: =out_loc!D32 -> -0.44517346 | C7: =out_loc!E32 -> -0.38814842 | D7: =out_loc!F32 -> -0.21368089 | E7: =out_loc!G32 -> -0.053059796 | F7: =out_loc!H32 -> -0.028109474 | G7: =out_loc!I32 -> 0.22261673 | H7: =out_loc!J32 -> 0.5312912 | I7: =out_loc!K32 -> 0.56607795 | ... AB7: =out_loc!AD32 -> 1.1425287
A8: Payback (y) | B8: =out_loc!D33 -> - | C8: =out_loc!E33 -> - | D8: =out_loc!F33 -> - | E8: =out_loc!G33 -> - | F8: =out_loc!H33 -> - | G8: =out_loc!I33 -> 16 | H8: =out_loc!J33 -> 11 | I8: =out_loc!K33 -> 11 | ... AB8: =out_loc!AD33 -> 7
A9: IRR (%) | B9: =out_loc!D34 -> -0.063591133 | C9: =out_loc!E34 -> -0.057564486 | D9: =out_loc!F34 -> -0.030717707 | E9: =out_loc!G34 -> -0.011461387 | F9: =out_loc!H34 -> -0.0095622736 | G9: =out_loc!I34 -> 0.022949343 | H9: =out_loc!J34 -> 0.056559485 | I9: =out_loc!K34 -> 0.059693657 | ... AB9: =out_loc!AD34 -> 0.12580191

Sheet in_loc
B1: Comment | C1: Dir | D1: n_2 | E1: n_25 | F1: n_10 | G1: b_2 | H1: b_25 | I1: b_10 | J1: m_2 | K1: m_25 | L1: m_10 | M1: =D1&"_pes" -> n_2_pes | N1: =E1&"_pes" -> n_25_pes | O1: =F1&"_pes" -> n_10_pes | P1: =G1&"_pes" -> b_2_pes | Q1: =H1&"_pes" -> b_25_pes | R1: =I1&"_pes" -> b_10_pes | S1: =J1&"_pes" -> m_2_pes | T1: =K1&"_pes" -> m_25_pes | U1: =L1&"_pes" -> m_10_pes | V1: =D1&"_opt" -> n_2_opt | W1: =E1&"_opt" -> n_25_opt | X1: =F1&"_opt" -> n_10_opt | Y1: =G1&"_opt" -> b_2_opt | Z1: =H1&"_opt" -> b_25_opt | AA1: =I1&"_opt" -> b_10_opt | AB1: =J1&"_opt" -> m_2_opt | AC1: =K1&"_opt" -> m_25_opt | AD1: =L1&"_opt" -> m_10_opt
A2: Cost (€)
A3: installation_pontoons_equipment_cost | C3: 1 | D3: 750000 | E3: 690000 | F3: 2050000 | G3: 307000 | H3: 295600 | I3: 625000 | J3: 277000 | K3: 265600 | L3: 535000 | M3: =D3*(1+in_gen!$C$44*$C3) -> 780000 | N3: =E3*(1+in_gen!$C$44*$C3) -> 717600 | O3: =F3*(1+in_gen!$C$44*$C3) -> 2132000 | P3: =G3*(1+in_gen!$C$44*$C3) -> 319280 | Q3: =H3*(1+in_gen!$C$44*$C3) -> 307424 | R3: =I3*(1+in_gen!$C$44*$C3) -> 650000 | S3: =J3*(1+in_gen!$C$44*$C3) -> 288080 | T3: =K3*(1+in_gen!$C$44*$C3) -> 276224 | U3: =L3*(1+in_gen!$C$44*$C3) -> 556400 | V3: =D3*(1+in_gen!$C$44*-$C3) -> 720000 | W3: =E3*(1+in_gen!$C$44*-$C3) -> 662400 | X3: =F3*(1+in_gen!$C$44*-$C3) -> 1968000 | Y3: =G3*(1+in_gen!$C$44*-$C3) -> 294720 | Z3: =H3*(1+in_gen!$C$44*-$C3) -> 283776 | AA3: =I3*(1+in_gen!$C$44*-$C3) -> 600000 | AB3: =J3*(1+in_gen!$C$44*-$C3) -> 265920 | AC3: =K3*(1+in_gen!$C$44*-$C3) -> 254976 | AD3: =L3*(1+in_gen!$C$44*-$C3) -> 513600
A4: installation_pontoons_fuel_cost | C4: 1 | D4: 321000 | E4: 299800 | F4: 861000 | G4: 38000 | H4: 36200 | I4: 82000 | J4: 21000 | K4: 20000 | L4: 42000 | M4: =D4*(1+in_gen!$C$44*$C4) -> 333840 | N4: =E4*(1+in_gen!$C$44*$C4) -> 311792 | O4: =F4*(1+in_gen!$C$44*$C4) -> 895440 | P4: =G4*(1+in_gen!$C$44*$C4) -> 39520 | Q4: =H4*(1+in_gen!$C$44*$C4) -> 37648 | R4: =I4*(1+in_gen!$C$44*$C4) -> 85280 | S4: =J4*(1+in_gen!$C$44*$C4) -> 21840 | T4: =K4*(1+in_gen!$C$44*$C4) -> 20800 | U4: =L4*(1+in_gen!$C$44*$C4) -> 43680 | V4: =D4*(1+in_gen!$C$44*-$C4) -> 308160 | W4: =E4*(1+in_gen!$C$44*-$C4) -> 287808 | X4: =F4*(1+in_gen!$C$44*-$C4) -> 826560 | Y4: =G4*(1+in_gen!$C$44*-$C4) -> 36480 | Z4: =H4*(1+in_gen!$C$44*-$C4) -> 34752 | AA4: =I4*(1+in_gen!$C$44*-$C4) -> 78720 | AB4: =J4*(1+in_gen!$C$44*-$C4) -> 20160 | AC4: =K4*(1+in_gen!$C$44*-$C4) -> 19200 | AD4: =L4*(1+in_gen!$C$44*-$C4) -> 40320
A5: installation_pontoons_personnel_cost | C5: 1 | D5: 65000 | E5: 72800 | F5: 234000 | G5: 95000 | H5: 91000 | I5: 260000 | J5: 82000 | K5: 78000 | L5: 221000 | M5: =D5*(1+in_gen!$C$44*$C5) -> 67600 | N5: =E5*(1+in_gen!$C$44*$C5) -> 75712 | O5: =F5*(1+in_gen!$C$44*$C5) -> 243360 | P5: =G5*(1+in_gen!$C$44*$C5) -> 98800 | Q5: =H5*(1+in_gen!$C$44*$C5) -> 94640 | R5: =I5*(1+in_gen!$C$44*$C5) -> 270400 | S5: =J5*(1+in_gen!$C$44*$C5) -> 85280 | T5: =K5*(1+in_gen!$C$44*$C5) -> 81120 | U5: =L5*(1+in_gen!$C$44*$C5) -> 229840 | V5: =D5*(1+in_gen!$C$44*-$C5) -> 62400 | W5: =E5*(1+in_gen!$C$44*-$C5) -> 69888 | X5: =F5*(1+in_gen!$C$44*-$C5) -> 224640 | Y5: =G5*(1+in_gen!$C$44*-$C5) -> 91200 | Z5: =H5*(1+in_gen!$C$44*-$C5) -> 87360 | AA5: =I5*(1+in_gen!$C$44*-$C5) -> 249600 | AB5: =J5*(1+in_gen!$C$44*-$C5) -> 78720 | AC5: =K5*(1+in_gen!$C$44*-$C5) -> 74880 | AD5: =L5*(1+in_gen!$C$44*-$C5) -> 212160
A6: installation_pv_system_equipment_cost | C6: 1 | D6: 560000 | E6: 400000 | F6: 1760000 | G6: 144000 | H6: 132600 | I6: 639000 | J6: 126000 | K6: 107800 | L6: 503000 | M6: =D6*(1+in_gen!$C$44*$C6) -> 582400 | N6: =E6*(1+in_gen!$C$44*$C6) -> 416000 | O6: =F6*(1+in_gen!$C$44*$C6) -> 1830400 | P6: =G6*(1+in_gen!$C$44*$C6) -> 149760 | Q6: =H6*(1+in_gen!$C$44*$C6) -> 137904 | R6: =I6*(1+in_gen!$C$44*$C6) -> 664560 | S6: =J6*(1+in_gen!$C$44*$C6) -> 131040 | T6: =K6*(1+in_gen!$C$44*$C6) -> 112112 | U6: =L6*(1+in_gen!$C$44*$C6) -> 523120 | V6: =D6*(1+in_gen!$C$44*-$C6) -> 537600 | W6: =E6*(1+in_gen!$C$44*-$C6) -> 384000 | X6: =F6*(1+in_gen!$C$44*-$C6) -> 1689600 | Y6: =G6*(1+in_gen!$C$44*-$C6) -> 138240 | Z6: =H6*(1+in_gen!$C$44*-$C6) -> 127296 | AA6: =I6*(1+in_gen!$C$44*-$C6) -> 613440 | AB6: =J6*(1+in_gen!$C$44*-$C6) -> 120960 | AC6: =K6*(1+in_gen!$C$44*-$C6) -> 103488 | AD6: =L6*(1+in_gen!$C$44*-$C6) -> 482880
A7: installation_pv_system_fuel_cost | C7: 1 | D7: 87000 | E7: 101800 | F7: 435000 | G7: 12000 | H7: 10600 | I7: 53000 | J7: 9000 | K7: 8000 | L7: 40000 | M7: =D7*(1+in_gen!$C$44*$C7) -> 90480 | N7: =E7*(1+in_gen!$C$44*$C7) -> 105872 | O7: =F7*(1+in_gen!$C$44*$C7) -> 452400 | P7: =G7*(1+in_gen!$C$44*$C7) -> 12480 | Q7: =H7*(1+in_gen!$C$44*$C7) -> 11024 | R7: =I7*(1+in_gen!$C$44*$C7) -> 55120 | S7: =J7*(1+in_gen!$C$44*$C7) -> 9360 | T7: =K7*(1+in_gen!$C$44*$C7) -> 8320 | U7: =L7*(1+in_gen!$C$44*$C7) -> 41600 | V7: =D7*(1+in_gen!$C$44*-$C7) -> 83520 | W7: =E7*(1+in_gen!$C$44*-$C7) -> 97728 | X7: =F7*(1+in_gen!$C$44*-$C7) -> 417600 | Y7: =G7*(1+in_gen!$C$44*-$C7) -> 11520 | Z7: =H7*(1+in_gen!$C$44*-$C7) -> 10176 | AA7: =I7*(1+in_gen!$C$44*-$C7) -> 50880 | AB7: =J7*(1+in_gen!$C$44*-$C7) -> 8640 | AC7: =K7*(1+in_gen!$C$44*-$C7) -> 7680 | AD7: =L7*(1+in_gen!$C$44*-$C7) -> 38400
A8: installation_pv_system_personnel_cost | C8: 1 | D8: 91000 | E8: 57200 | F8: 267000 | G8: 85000 | H8: 74800 | I8: 358000 | J8: 69000 | K8: 61800 | L8: 283000 | M8: =D8*(1+in_gen!$C$44*$C8) -> 94640 | N8: =E8*(1+in_gen!$C$44*$C8) -> 59488 | O8: =F8*(1+in_gen!$C$44*$C8) -> 277680 | P8: =G8*(1+in_gen!$C$44*$C8) -> 88400 | Q8: =H8*(1+in_gen!$C$44*$C8) -> 77792 | R8: =I8*(1+in_gen!$C$44*$C8) -> 372320 | S8: =J8*(1+in_gen!$C$44*$C8) -> 71760 | T8: =K8*(1+in_gen!$C$44*$C8) -> 64272 | U8: =L8*(1+in_gen!$C$44*$C8) -> 294320 | V8: =D8*(1+in_gen!$C$44*-$C8) -> 87360 | W8: =E8*(1+in_gen!$C$44*-$C8) -> 54912 | X8: =F8*(1+in_gen!$C$44*-$C8) -> 256320 | Y8: =G8*(1+in_gen!$C$44*-$C8) -> 81600 | Z8: =H8*(1+in_gen!$C$44*-$C8) -> 71808 | AA8: =I8*(1+in_gen!$C$44*-$C8) -> 343680 | AB8: =J8*(1+in_gen!$C$44*-$C8) -> 66240 | AC8: =K8*(1+in_gen!$C$44*-$C8) -> 59328 | AD8: =L8*(1+in_gen!$C$44*-$C8) -> 271680
A9: maintenance_pontoons_equipment_cost | C9: 1 | D9: 70000 | E9: 38000 | F9: 130000 | G9: 33000 | H9: 28200 | I9: 87000 | J9: 27000 | K9: 22200 | L9: 63000 | M9: =D9*(1+in_gen!$C$44*$C9) -> 72800 | N9: =E9*(1+in_gen!$C$44*$C9) -> 39520 | O9: =F9*(1+in_gen!$C$44*$C9) -> 135200 | P9: =G9*(1+in_gen!$C$44*$C9) -> 34320 | Q9: =H9*(1+in_gen!$C$44*$C9) -> 29328 | R9: =I9*(1+in_gen!$C$44*$C9) -> 90480 | S9: =J9*(1+in_gen!$C$44*$C9) -> 28080 | T9: =K9*(1+in_gen!$C$44*$C9) -> 23088 | U9: =L9*(1+in_gen!$C$44*$C9) -> 65520 | V9: =D9*(1+in_gen!$C$44*-$C9) -> 67200 | W9: =E9*(1+in_gen!$C$44*-$C9) -> 36480 | X9: =F9*(1+in_gen!$C$44*-$C9) -> 124800 | Y9: =G9*(1+in_gen!$C$44*-$C9) -> 31680 | Z9: =H9*(1+in_gen!$C$44*-$C9) -> 27072 | AA9: =I9*(1+in_gen!$C$44*-$C9) -> 83520 | AB9: =J9*(1+in_gen!$C$44*-$C9) -> 25920 | AC9: =K9*(1+in_gen!$C$44*-$C9) -> 21312 | AD9: =L9*(1+in_gen!$C$44*-$C9) -> 60480
A10: maintenance_pontoons_fuel_cost | C10: 1 | D10: 14000 | E10: 6800 | F10: 24000 | G10: 5000 | H10: 4000 | I10: 12000 | J10: 2000 | K10: 1200 | L10: 4000 | M10: =D10*(1+in_gen!$C$44*$C10) -> 14560 | N10: =E10*(1+in_gen!$C$44*$C10) -> 7072 | O10: =F10*(1+in_gen!$C$44*$C10) -> 24960 | P10: =G10*(1+in_gen!$C$44*$C10) -> 5200 | Q10: =H10*(1+in_gen!$C$44*$C10) -> 4160 | R10: =I10*(1+in_gen!$C$44*$C10) -> 12480 | S10: =J10*(1+in_gen!$C$44*$C10) -> 2080 | T10: =K10*(1+in_gen!$C$44*$C10) -> 1248 | U10: =L10*(1+in_gen!$C$44*$C10) -> 4160 | V10: =D10*(1+in_gen!$C$44*-$C10) -> 13440 | W10: =E10*(1+in_gen!$C$44*-$C10) -> 6528 | X10: =F10*(1+in_gen!$C$44*-$C10) -> 23040 | Y10: =G10*(1+in_gen!$C$44*-$C10) -> 4800 | Z10: =H10*(1+in_gen!$C$44*-$C10) -> 3840 | AA10: =I10*(1+in_gen!$C$44*-$C10) -> 11520 | AB10: =J10*(1+in_gen!$C$44*-$C10) -> 1920 | AC10: =K10*(1+in_gen!$C$44*-$C10) -> 1152 | AD10: =L10*(1+in_gen!$C$44*-$C10) -> 3840
A11: maintenance_pontoons_personnel_cost | C11: 1 | D11: 23000 | E11: 12400 | F11: 43000 | G11: 20000 | H11: 15600 | I11: 49000 | J11: 17000 | K11: 12400 | L11: 36000 | M11: =D11*(1+in_gen!$C$44*$C11) -> 23920 | N11: =E11*(1+in_gen!$C$44*$C11) -> 12896 | O11: =F11*(1+in_gen!$C$44*$C11) -> 44720 | P11: =G11*(1+in_gen!$C$44*$C11) -> 20800 | Q11: =H11*(1+in_gen!$C$44*$C11) -> 16224 | R11: =I11*(1+in_gen!$C$44*$C11) -> 50960 | S11: =J11*(1+in_gen!$C$44*$C11) -> 17680 | T11: =K11*(1+in_gen!$C$44*$C11) -> 12896 | U11: =L11*(1+in_gen!$C$44*$C11) -> 37440 | V11: =D11*(1+in_gen!$C$44*-$C11) -> 22080 | W11: =E11*(1+in_gen!$C$44*-$C11) -> 11904 | X11: =F11*(1+in_gen!$C$44*-$C11) -> 41280 | Y11: =G11*(1+in_gen!$C$44*-$C11) -> 19200 | Z11: =H11*(1+in_gen!$C$44*-$C11) -> 14976 | AA11: =I11*(1+in_gen!$C$44*-$C11) -> 47040 | AB11: =J11*(1+in_gen!$C$44*-$C11) -> 16320 | AC11: =K11*(1+in_gen!$C$44*-$C11) -> 11904 | AD11: =L11*(1+in_gen!$C$44*-$C11) -> 34560
A12: replacement_of_pv_system_equipment_cost | C12: 1 | D12: 600000 | E12: 408000 | F12: 2040000 | G12: 167000 | H12: 145200 | I12: 769000 | J12: 149000 | K12: 130800 | L12: 679000 | M12: =D12*(1+in_gen!$C$44*$C12) -> 624000 | N12: =E12*(1+in_gen!$C$44*$C12) -> 424320 | O12: =F12*(1+in_gen!$C$44*$C12) -> 2121600 | P12: =G12*(1+in_gen!$C$44*$C12) -> 173680 | Q12: =H12*(1+in_gen!$C$44*$C12) -> 151008 | R12: =I12*(1+in_gen!$C$44*$C12) -> 799760 | S12: =J12*(1+in_gen!$C$44*$C12) -> 154960 | T12: =K12*(1+in_gen!$C$44*$C12) -> 136032 | U12: =L12*(1+in_gen!$C$44*$C12) -> 706160 | V12: =D12*(1+in_gen!$C$44*-$C12) -> 576000 | W12: =E12*(1+in_gen!$C$44*-$C12) -> 391680 | X12: =F12*(1+in_gen!$C$44*-$C12) -> 1958400 | Y12: =G12*(1+in_gen!$C$44*-$C12) -> 160320 | Z12: =H12*(1+in_gen!$C$44*-$C12) -> 139392 | AA12: =I12*(1+in_gen!$C$44*-$C12) -> 738240 | AB12: =J12*(1+in_gen!$C$44*-$C12) -> 143040 | AC12: =K12*(1+in_gen!$C$44*-$C12) -> 125568 | AD12: =L12*(1+in_gen!$C$44*-$C12) -> 651840
A13: replacement_of_pv_system_fuel_cost | C13: 1 | D13: 90000 | E13: 103000 | F13: 503000 | G13: 17000 | H13: 15600 | I13: 80000 | J13: 13000 | K13: 12000 | L13: 61000 | M13: =D13*(1+in_gen!$C$44*$C13) -> 93600 | N13: =E13*(1+in_gen!$C$44*$C13) -> 107120 | O13: =F13*(1+in_gen!$C$44*$C13) -> 523120 | P13: =G13*(1+in_gen!$C$44*$C13) -> 17680 | Q13: =H13*(1+in_gen!$C$44*$C13) -> 16224 | R13: =I13*(1+in_gen!$C$44*$C13) -> 83200 | S13: =J13*(1+in_gen!$C$44*$C13) -> 13520 | T13: =K13*(1+in_gen!$C$44*$C13) -> 12480 | U13: =L13*(1+in_gen!$C$44*$C13) -> 63440 | V13: =D13*(1+in_gen!$C$44*-$C13) -> 86400 | W13: =E13*(1+in_gen!$C$44*-$C13) -> 98880 | X13: =F13*(1+in_gen!$C$44*-$C13) -> 482880 | Y13: =G13*(1+in_gen!$C$44*-$C13) -> 16320 | Z13: =H13*(1+in_gen!$C$44*-$C13) -> 14976 | AA13: =I13*(1+in_gen!$C$44*-$C13) -> 76800 | AB13: =J13*(1+in_gen!$C$44*-$C13) -> 12480 | AC13: =K13*(1+in_gen!$C$44*-$C13) -> 11520 | AD13: =L13*(1+in_gen!$C$44*-$C13) -> 58560
A14: replacement_of_pv_system_personnel_cost | C14: 1 | D14: 111000 | E14: 84600 | F14: 423000 | G14: 134000 | H14: 117000 | I14: 611000 | J14: 108000 | K14: 96200 | L14: 481000 | M14: =D14*(1+in_gen!$C$44*$C14) -> 115440 | N14: =E14*(1+in_gen!$C$44*$C14) -> 87984 | O14: =F14*(1+in_gen!$C$44*$C14) -> 439920 | P14: =G14*(1+in_gen!$C$44*$C14) -> 139360 | Q14: =H14*(1+in_gen!$C$44*$C14) -> 121680 | R14: =I14*(1+in_gen!$C$44*$C14) -> 635440 | S14: =J14*(1+in_gen!$C$44*$C14) -> 112320 | T14: =K14*(1+in_gen!$C$44*$C14) -> 100048 | U14: =L14*(1+in_gen!$C$44*$C14) -> 500240 | V14: =D14*(1+in_gen!$C$44*-$C14) -> 106560 | W14: =E14*(1+in_gen!$C$44*-$C14) -> 81216 | X14: =F14*(1+in_gen!$C$44*-$C14) -> 406080 | Y14: =G14*(1+in_gen!$C$44*-$C14) -> 128640 | Z14: =H14*(1+in_gen!$C$44*-$C14) -> 112320 | AA14: =I14*(1+in_gen!$C$44*-$C14) -> 586560 | AB14: =J14*(1+in_gen!$C$44*-$C14) -> 103680 | AC14: =K14*(1+in_gen!$C$44*-$C14) -> 92352 | AD14: =L14*(1+in_gen!$C$44*-$C14) -> 461760
A15: inverters_transformers_cost | C15: 1 | D15: 36000 | E15: 36000 | F15: 300000 | G15: 27000 | H15: 27000 | I15: 220000 | J15: 27000 | K15: 27000 | L15: 240000 | M15: =D15*(1+in_gen!$C$44*$C15) -> 37440 | N15: =E15*(1+in_gen!$C$44*$C15) -> 37440 | O15: =F15*(1+in_gen!$C$44*$C15) -> 312000 | P15: =G15*(1+in_gen!$C$44*$C15) -> 28080 | Q15: =H15*(1+in_gen!$C$44*$C15) -> 28080 | R15: =I15*(1+in_gen!$C$44*$C15) -> 228800 | S15: =J15*(1+in_gen!$C$44*$C15) -> 28080 | T15: =K15*(1+in_gen!$C$44*$C15) -> 28080 | U15: =L15*(1+in_gen!$C$44*$C15) -> 249600 | V15: =D15*(1+in_gen!$C$44*-$C15) -> 34560 | W15: =E15*(1+in_gen!$C$44*-$C15) -> 34560 | X15: =F15*(1+in_gen!$C$44*-$C15) -> 288000 | Y15: =G15*(1+in_gen!$C$44*-$C15) -> 25920 | Z15: =H15*(1+in_gen!$C$44*-$C15) -> 25920 | AA15: =I15*(1+in_gen!$C$44*-$C15) -> 211200 | AB15: =J15*(1+in_gen!$C$44*-$C15) -> 25920 | AC15: =K15*(1+in_gen!$C$44*-$C15) -> 25920 | AD15: =L15*(1+in_gen!$C$44*-$C15) -> 230400
A16: solar_maintenance_cost_per_kw_per_year | B16: Boat trips to site already included in pontoon maintenance. Larger size reduces cost. Waves increase cost. Robust panels decrease costs. Cooling reduces costs. Otherwise same as for land. | C16: 1 | D16: 20 | E16: 20 | F16: 15 | G16: 16 | H16: 16 | I16: 12 | J16: 10 | K16: 10 | L16: 7.5 | M16: =D16*(1+in_gen!$C$44*$C16) -> 20.8 | N16: =E16*(1+in_gen!$C$44*$C16) -> 20.8 | O16: =F16*(1+in_gen!$C$44*$C16) -> 15.6 | P16: =G16*(1+in_gen!$C$44*$C16) -> 16.64 | Q16: =H16*(1+in_gen!$C$44*$C16) -> 16.64 | R16: =I16*(1+in_gen!$C$44*$C16) -> 12.48 | S16: =J16*(1+in_gen!$C$44*$C16) -> 10.4 | T16: =K16*(1+in_gen!$C$44*$C16) -> 10.4 | U16: =L16*(1+in_gen!$C$44*$C16) -> 7.8 | V16: =D16*(1+in_gen!$C$44*-$C16) -> 19.2 | W16: =E16*(1+in_gen!$C$44*-$C16) -> 19.2 | X16: =F16*(1+in_gen!$C$44*-$C16) -> 14.4 | Y16: =G16*(1+in_gen!$C$44*-$C16) -> 15.36 | Z16: =H16*(1+in_gen!$C$44*-$C16) -> 15.36 | AA16: =I16*(1+in_gen!$C$44*-$C16) -> 11.52 | AB16: =J16*(1+in_gen!$C$44*-$C16) -> 9.6 | AC16: =K16*(1+in_gen!$C$44*-$C16) -> 9.6 | AD16: =L16*(1+in_gen!$C$44*-$C16) -> 7.2
A18: Count
A19: anchors_count | C19: 0 | D19: 16 | E19: 16 | F19: 38 | G19: 16 | H19: 16 | I19: 26 | J19: 16 | K19: 16 | L19: 26 | M19: =D19*(1+in_gen!$C$44*$C19) -> 16 | N19: =E19*(1+in_gen!$C$44*$C19) -> 16 | O19: =F19*(1+in_gen!$C$44*$C19) -> 38 | P19: =G19*(1+in_gen!$C$44*$C19) -> 16 | Q19: =H19*(1+in_gen!$C$44*$C19) -> 16 | R19: =I19*(1+in_gen!$C$44*$C19) -> 26 | S19: =J19*(1+in_gen!$C$44*$C19) -> 16 | T19: =K19*(1+in_gen!$C$44*$C19) -> 16 | U19: =L19*(1+in_gen!$C$44*$C19) -> 26 | V19: =D19*(1+in_gen!$C$44*-$C19) -> 16 | W19: =E19*(1+in_gen!$C$44*-$C19) -> 16 | X19: =F19*(1+in_gen!$C$44*-$C19) -> 38 | Y19: =G19*(1+in_gen!$C$44*-$C19) -> 16 | Z19: =H19*(1+in_gen!$C$44*-$C19) -> 16 | AA19: =I19*(1+in_gen!$C$44*-$C19) -> 26 | AB19: =J19*(1+in_gen!$C$44*-$C19) -> 16 | AC19: =K19*(1+in_gen!$C$44*-$C19) -> 16 | AD19: =L19*(1+in_gen!$C$44*-$C19) -> 26
A20: pontoons_count | C20: 0 | D20: 32 | E20: 32 | F20: 91 | G20: 32 | H20: 32 | I20: 91 | J20: 32 | K20: 32 | L20: 91 | M20: =D20*(1+in_gen!$C$44*$C20) -> 32 | N20: =E20*(1+in_gen!$C$44*$C20) -> 32 | O20: =F20*(1+in_gen!$C$44*$C20) -> 91 | P20: =G20*(1+in_gen!$C$44*$C20) -> 32 | Q20: =H20*(1+in_gen!$C$44*$C20) -> 32 | R20: =I20*(1+in_gen!$C$44*$C20) -> 91 | S20: =J20*(1+in_gen!$C$44*$C20) -> 32 | T20: =K20*(1+in_gen!$C$44*$C20) -> 32 | U20: =L20*(1+in_gen!$C$44*$C20) -> 91 | V20: =D20*(1+in_gen!$C$44*-$C20) -> 32 | W20: =E20*(1+in_gen!$C$44*-$C20) -> 32 | X20: =F20*(1+in_gen!$C$44*-$C20) -> 91 | Y20: =G20*(1+in_gen!$C$44*-$C20) -> 32 | Z20: =H20*(1+in_gen!$C$44*-$C20) -> 32 | AA20: =I20*(1+in_gen!$C$44*-$C20) -> 91 | AB20: =J20*(1+in_gen!$C$44*-$C20) -> 32 | AC20: =K20*(1+in_gen!$C$44*-$C20) -> 32 | AD20: =L20*(1+in_gen!$C$44*-$C20) -> 91
A21: matrices_per_quadrant | C21: 0 | D21: 17 | E21: 17 | F21: 17 | G21: 17 | H21: 17 | I21: 17 | J21: 17 | K21: 17 | L21: 17 | M21: =D21*(1+in_gen!$C$44*$C21) -> 17 | N21: =E21*(1+in_gen!$C$44*$C21) -> 17 | O21: =F21*(1+in_gen!$C$44*$C21) -> 17 | P21: =G21*(1+in_gen!$C$44*$C21) -> 17 | Q21: =H21*(1+in_gen!$C$44*$C21) -> 17 | R21: =I21*(1+in_gen!$C$44*$C21) -> 17 | S21: =J21*(1+in_gen!$C$44*$C21) -> 17 | T21: =K21*(1+in_gen!$C$44*$C21) -> 17 | U21: =L21*(1+in_gen!$C$44*$C21) -> 17 | V21: =D21*(1+in_gen!$C$44*-$C21) -> 17 | W21: =E21*(1+in_gen!$C$44*-$C21) -> 17 | X21: =F21*(1+in_gen!$C$44*-$C21) -> 17 | Y21: =G21*(1+in_gen!$C$44*-$C21) -> 17 | Z21: =H21*(1+in_gen!$C$44*-$C21) -> 17 | AA21: =I21*(1+in_gen!$C$44*-$C21) -> 17 | AB21: =J21*(1+in_gen!$C$44*-$C21) -> 17 | AC21: =K21*(1+in_gen!$C$44*-$C21) -> 17 | AD21: =L21*(1+in_gen!$C$44*-$C21) -> 17
A22: rings_count | C22: 0 | D22: 1 | E22: 5 | F22: 1 | G22: 1 | H22: 5 | I22: 1 | J22: 1 | K22: 5 | L22: 1 | M22: =D22*(1+in_gen!$C$44*$C22) -> 1 | N22: =E22*(1+in_gen!$C$44*$C22) -> 5 | O22: =F22*(1+in_gen!$C$44*$C22) -> 1 | P22: =G22*(1+in_gen!$C$44*$C22) -> 1 | Q22: =H22*(1+in_gen!$C$44*$C22) -> 5 | R22: =I22*(1+in_gen!$C$44*$C22) -> 1 | S22: =J22*(1+in_gen!$C$44*$C22) -> 1 | T22: =K22*(1+in_gen!$C$44*$C22) -> 5 | U22: =L22*(1+in_gen!$C$44*$C22) -> 1 | V22: =D22*(1+in_gen!$C$44*-$C22) -> 1 | W22: =E22*(1+in_gen!$C$44*-$C22) -> 5 | X22: =F22*(1+in_gen!$C$44*-$C22) -> 1 | Y22: =G22*(1+in_gen!$C$44*-$C22) -> 1 | Z22: =H22*(1+in_gen!$C$44*-$C22) -> 5 | AA22: =I22*(1+in_gen!$C$44*-$C22) -> 1 | AB22: =J22*(1+in_gen!$C$44*-$C22) -> 1 | AC22: =K22*(1+in_gen!$C$44*-$C22) -> 5 | AD22: =L22*(1+in_gen!$C$44*-$C22) -> 1
A24: Weight (t)
A25: anchor_weight | C25: 0 | D25: 46.7 | E25: 46.7 | F25: 58.41 | G25: 9.5 | H25: 9.5 | I25: 24.22 | J25: 26.38 | K25: 26.38 | L25: 58.41 | M25: =D25*(1+in_gen!$C$44*$C25) -> 46.7 | N25: =E25*(1+in_gen!$C$44*$C25) -> 46.7 | O25: =F25*(1+in_gen!$C$44*$C25) -> 58.41 | P25: =G25*(1+in_gen!$C$44*$C25) -> 9.5 | Q25: =H25*(1+in_gen!$C$44*$C25) -> 9.5 | R25: =I25*(1+in_gen!$C$44*$C25) -> 24.22 | S25: =J25*(1+in_gen!$C$44*$C25) -> 26.38 | T25: =K25*(1+in_gen!$C$44*$C25) -> 26.38 | U25: =L25*(1+in_gen!$C$44*$C25) -> 58.41 | V25: =D25*(1+in_gen!$C$44*-$C25) -> 46.7 | W25: =E25*(1+in_gen!$C$44*-$C25) -> 46.7 | X25: =F25*(1+in_gen!$C$44*-$C25) -> 58.41 | Y25: =G25*(1+in_gen!$C$44*-$C25) -> 9.5 | Z25: =H25*(1+in_gen!$C$44*-$C25) -> 9.5 | AA25: =I25*(1+in_gen!$C$44*-$C25) -> 24.22 | AB25: =J25*(1+in_gen!$C$44*-$C25) -> 26.38 | AC25: =K25*(1+in_gen!$C$44*-$C25) -> 26.38 | AD25: =L25*(1+in_gen!$C$44*-$C25) -> 58.41
A26: chain_weight | C26: 0 | D26: 18.27 | E26: 18.27 | F26: 31.92 | G26: 11.82 | H26: 11.82 | I26: 25.35 | J26: 12.72 | K26: 12.72 | L26: 30.61 | M26: =D26*(1+in_gen!$C$44*$C26) -> 18.27 | N26: =E26*(1+in_gen!$C$44*$C26) -> 18.27 | O26: =F26*(1+in_gen!$C$44*$C26) -> 31.92 | P26: =G26*(1+in_gen!$C$44*$C26) -> 11.82 | Q26: =H26*(1+in_gen!$C$44*$C26) -> 11.82 | R26: =I26*(1+in_gen!$C$44*$C26) -> 25.35 | S26: =J26*(1+in_gen!$C$44*$C26) -> 12.72 | T26: =K26*(1+in_gen!$C$44*$C26) -> 12.72 | U26: =L26*(1+in_gen!$C$44*$C26) -> 30.61 | V26: =D26*(1+in_gen!$C$44*-$C26) -> 18.27 | W26: =E26*(1+in_gen!$C$44*-$C26) -> 18.27 | X26: =F26*(1+in_gen!$C$44*-$C26) -> 31.92 | Y26: =G26*(1+in_gen!$C$44*-$C26) -> 11.82 | Z26: =H26*(1+in_gen!$C$44*-$C26) -> 11.82 | AA26: =I26*(1+in_gen!$C$44*-$C26) -> 25.35 | AB26: =J26*(1+in_gen!$C$44*-$C26) -> 12.72 | AC26: =K26*(1+in_gen!$C$44*-$C26) -> 12.72 | AD26: =L26*(1+in_gen!$C$44*-$C26) -> 30.61
A27: pvc_pipe_weight | C27: 0 | D27: 13.6 | E27: 68 | F27: 56.9 | G27: 13.6 | H27: 68 | I27: 56.9 | J27: 13.6 | K27: 68 | L27: 56.9 | M27: =D27*(1+in_gen!$C$44*$C27) -> 13.6 | N27: =E27*(1+in_gen!$C$44*$C27) -> 68 | O27: =F27*(1+in_gen!$C$44*$C27) -> 56.9 | P27: =G27*(1+in_gen!$C$44*$C27) -> 13.6 | Q27: =H27*(1+in_gen!$C$44*$C27) -> 68 | R27: =I27*(1+in_gen!$C$44*$C27) -> 56.9 | S27: =J27*(1+in_gen!$C$44*$C27) -> 13.6 | T27: =K27*(1+in_gen!$C$44*$C27) -> 68 | U27: =L27*(1+in_gen!$C$44*$C27) -> 56.9 | V27: =D27*(1+in_gen!$C$44*-$C27) -> 13.6 | W27: =E27*(1+in_gen!$C$44*-$C27) -> 68 | X27: =F27*(1+in_gen!$C$44*-$C27) -> 56.9 | Y27: =G27*(1+in_gen!$C$44*-$C27) -> 13.6 | Z27: =H27*(1+in_gen!$C$44*-$C27) -> 68 | AA27: =I27*(1+in_gen!$C$44*-$C27) -> 56.9 | AB27: =J27*(1+in_gen!$C$44*-$C27) -> 13.6 | AC27: =K27*(1+in_gen!$C$44*-$C27) -> 68 | AD27: =L27*(1+in_gen!$C$44*-$C27) -> 56.9
A28: polypropylene_rope_weight | C28: 0 | D28: 0.9 | E28: 4.5 | F28: 4.1 | G28: 0.9 | H28: 4.5 | I28: 4.1 | J28: 0.9 | K28: 4.5 | L28: 4.1 | M28: =D28*(1+in_gen!$C$44*$C28) -> 0.9 | N28: =E28*(1+in_gen!$C$44*$C28) -> 4.5 | O28: =F28*(1+in_gen!$C$44*$C28) -> 4.1 | P28: =G28*(1+in_gen!$C$44*$C28) -> 0.9 | Q28: =H28*(1+in_gen!$C$44*$C28) -> 4.5 | R28: =I28*(1+in_gen!$C$44*$C28) -> 4.1 | S28: =J28*(1+in_gen!$C$44*$C28) -> 0.9 | T28: =K28*(1+in_gen!$C$44*$C28) -> 4.5 | U28: =L28*(1+in_gen!$C$44*$C28) -> 4.1 | V28: =D28*(1+in_gen!$C$44*-$C28) -> 0.9 | W28: =E28*(1+in_gen!$C$44*-$C28) -> 4.5 | X28: =F28*(1+in_gen!$C$44*-$C28) -> 4.1 | Y28: =G28*(1+in_gen!$C$44*-$C28) -> 0.9 | Z28: =H28*(1+in_gen!$C$44*-$C28) -> 4.5 | AA28: =I28*(1+in_gen!$C$44*-$C28) -> 4.1 | AB28: =J28*(1+in_gen!$C$44*-$C28) -> 0.9 | AC28: =K28*(1+in_gen!$C$44*-$C28) -> 4.5 | AD28: =L28*(1+in_gen!$C$44*-$C28) -> 4.1
A30: Distance (m)
A31: solar_pipe_distance | C31: 0 | D31: 7.5 | E31: 7.5 | F31: 15 | G31: 7.5 | H31: 7.5 | I31: 15 | J31: 7.5 | K31: 7.5 | L31: 15 | M31: =D31*(1+in_gen!$C$44*$C31) -> 7.5 | N31: =E31*(1+in_gen!$C$44*$C31) -> 7.5 | O31: =F31*(1+in_gen!$C$44*$C31) -> 15 | P31: =G31*(1+in_gen!$C$44*$C31) -> 7.5 | Q31: =H31*(1+in_gen!$C$44*$C31) -> 7.5 | R31: =I31*(1+in_gen!$C$44*$C31) -> 15 | S31: =J31*(1+in_gen!$C$44*$C31) -> 7.5 | T31: =K31*(1+in_gen!$C$44*$C31) -> 7.5 | U31: =L31*(1+in_gen!$C$44*$C31) -> 15 | V31: =D31*(1+in_gen!$C$44*-$C31) -> 7.5 | W31: =E31*(1+in_gen!$C$44*-$C31) -> 7.5 | X31: =F31*(1+in_gen!$C$44*-$C31) -> 15 | Y31: =G31*(1+in_gen!$C$44*-$C31) -> 7.5 | Z31: =H31*(1+in_gen!$C$44*-$C31) -> 7.5 | AA31: =I31*(1+in_gen!$C$44*-$C31) -> 15 | AB31: =J31*(1+in_gen!$C$44*-$C31) -> 7.5 | AC31: =K31*(1+in_gen!$C$44*-$C31) -> 7.5 | AD31: =L31*(1+in_gen!$C$44*-$C31) -> 15
A32: pipe_wavebreaker_distance | C32: 0 | D32: 7.5 | E32: 7.5 | F32: 15 | G32: 7.5 | H32: 7.5 | I32: 15 | J32: 7.5 | K32: 7.5 | L32: 15 | M32: =D32*(1+in_gen!$C$44*$C32) -> 7.5 | N32: =E32*(1+in_gen!$C$44*$C32) -> 7.5 | O32: =F32*(1+in_gen!$C$44*$C32) -> 15 | P32: =G32*(1+in_gen!$C$44*$C32) -> 7.5 | Q32: =H32*(1+in_gen!$C$44*$C32) -> 7.5 | R32: =I32*(1+in_gen!$C$44*$C32) -> 15 | S32: =J32*(1+in_gen!$C$44*$C32) -> 7.5 | T32: =K32*(1+in_gen!$C$44*$C32) -> 7.5 | U32: =L32*(1+in_gen!$C$44*$C32) -> 15 | V32: =D32*(1+in_gen!$C$44*-$C32) -> 7.5 | W32: =E32*(1+in_gen!$C$44*-$C32) -> 7.5 | X32: =F32*(1+in_gen!$C$44*-$C32) -> 15 | Y32: =G32*(1+in_gen!$C$44*-$C32) -> 7.5 | Z32: =H32*(1+in_gen!$C$44*-$C32) -> 7.5 | AA32: =I32*(1+in_gen!$C$44*-$C32) -> 15 | AB32: =J32*(1+in_gen!$C$44*-$C32) -> 7.5 | AC32: =K32*(1+in_gen!$C$44*-$C32) -> 7.5 | AD32: =L32*(1+in_gen!$C$44*-$C32) -> 15
A33: matrix_side_length | C33: 0 | D33: 14 | E33: 14 | F33: 28 | G33: 14 | H33: 14 | I33: 28 | J33: 14 | K33: 14 | L33: 28 | M33: =D33*(1+in_gen!$C$44*$C33) -> 14 | N33: =E33*(1+in_gen!$C$44*$C33) -> 14 | O33: =F33*(1+in_gen!$C$44*$C33) -> 28 | P33: =G33*(1+in_gen!$C$44*$C33) -> 14 | Q33: =H33*(1+in_gen!$C$44*$C33) -> 14 | R33: =I33*(1+in_gen!$C$44*$C33) -> 28 | S33: =J33*(1+in_gen!$C$44*$C33) -> 14 | T33: =K33*(1+in_gen!$C$44*$C33) -> 14 | U33: =L33*(1+in_gen!$C$44*$C33) -> 28 | V33: =D33*(1+in_gen!$C$44*-$C33) -> 14 | W33: =E33*(1+in_gen!$C$44*-$C33) -> 14 | X33: =F33*(1+in_gen!$C$44*-$C33) -> 28 | Y33: =G33*(1+in_gen!$C$44*-$C33) -> 14 | Z33: =H33*(1+in_gen!$C$44*-$C33) -> 14 | AA33: =I33*(1+in_gen!$C$44*-$C33) -> 28 | AB33: =J33*(1+in_gen!$C$44*-$C33) -> 14 | AC33: =K33*(1+in_gen!$C$44*-$C33) -> 14 | AD33: =L33*(1+in_gen!$C$44*-$C33) -> 28
A34: distance_to_shore | C34: 0 | D34: 170000 | E34: 170000 | F34: 170000 | G34: 30000 | H34: 30000 | I34: 30000 | J34: 11000 | K34: 11000 | L34: 11000 | M34: =D34*(1+in_gen!$C$44*$C34) -> 170000 | N34: =E34*(1+in_gen!$C$44*$C34) -> 170000 | O34: =F34*(1+in_gen!$C$44*$C34) -> 170000 | P34: =G34*(1+in_gen!$C$44*$C34) -> 30000 | Q34: =H34*(1+in_gen!$C$44*$C34) -> 30000 | R34: =I34*(1+in_gen!$C$44*$C34) -> 30000 | S34: =J34*(1+in_gen!$C$44*$C34) -> 11000 | T34: =K34*(1+in_gen!$C$44*$C34) -> 11000 | U34: =L34*(1+in_gen!$C$44*$C34) -> 11000 | V34: =D34*(1+in_gen!$C$44*-$C34) -> 170000 | W34: =E34*(1+in_gen!$C$44*-$C34) -> 170000 | X34: =F34*(1+in_gen!$C$44*-$C34) -> 170000 | Y34: =G34*(1+in_gen!$C$44*-$C34) -> 30000 | Z34: =H34*(1+in_gen!$C$44*-$C34) -> 30000 | AA34: =I34*(1+in_gen!$C$44*-$C34) -> 30000 | AB34: =J34*(1+in_gen!$C$44*-$C34) -> 11000 | AC34: =K34*(1+in_gen!$C$44*-$C34) -> 11000 | AD34: =L34*(1+in_gen!$C$44*-$C34) -> 11000
A35: panel_transport_km | C35: 0 | D35: 620 | E35: 620 | F35: 620 | G35: 909 | H35: 909 | I35: 909 | J35: 2901 | K35: 2901 | L35: 2901 | M35: =D35*(1+in_gen!$C$44*$C35) -> 620 | N35: =E35*(1+in_gen!$C$44*$C35) -> 620 | O35: =F35*(1+in_gen!$C$44*$C35) -> 620 | P35: =G35*(1+in_gen!$C$44*$C35) -> 909 | Q35: =H35*(1+in_gen!$C$44*$C35) -> 909 | R35: =I35*(1+in_gen!$C$44*$C35) -> 909 | S35: =J35*(1+in_gen!$C$44*$C35) -> 2901 | T35: =K35*(1+in_gen!$C$44*$C35) -> 2901 | U35: =L35*(1+in_gen!$C$44*$C35) -> 2901 | V35: =D35*(1+in_gen!$C$44*-$C35) -> 620 | W35: =E35*(1+in_gen!$C$44*-$C35) -> 620 | X35: =F35*(1+in_gen!$C$44*-$C35) -> 620 | Y35: =G35*(1+in_gen!$C$44*-$C35) -> 909 | Z35: =H35*(1+in_gen!$C$44*-$C35) -> 909 | AA35: =I35*(1+in_gen!$C$44*-$C35) -> 909 | AB35: =J35*(1+in_gen!$C$44*-$C35) -> 2901 | AC35: =K35*(1+in_gen!$C$44*-$C35) -> 2901 | AD35: =L35*(1+in_gen!$C$44*-$C35) -> 2901
A37: Percentages (%)
A38: solar_degradation_yearly | C38: 1 | D38: 0.00375 | E38: 0.00375 | F38: 0.005 | G38: 0.001875 | H38: 0.001875 | I38: 0.0025 | J38: 0.000825 | K38: 0.000825 | L38: 0.00125 | M38: =D38*(1+in_gen!$C$44*$C38) -> 0.0039 | N38: =E38*(1+in_gen!$C$44*$C38) -> 0.0039 | O38: =F38*(1+in_gen!$C$44*$C38) -> 0.0052 | P38: =G38*(1+in_gen!$C$44*$C38) -> 0.00195 | Q38: =H38*(1+in_gen!$C$44*$C38) -> 0.00195 | R38: =I38*(1+in_gen!$C$44*$C38) -> 0.0026 | S38: =J38*(1+in_gen!$C$44*$C38) -> 0.000858 | T38: =K38*(1+in_gen!$C$44*$C38) -> 0.000858 | U38: =L38*(1+in_gen!$C$44*$C38) -> 0.0013 | V38: =D38*(1+in_gen!$C$44*-$C38) -> 0.0036 | W38: =E38*(1+in_gen!$C$44*-$C38) -> 0.0036 | X38: =F38*(1+in_gen!$C$44*-$C38) -> 0.0048 | Y38: =G38*(1+in_gen!$C$44*-$C38) -> 0.0018 | Z38: =H38*(1+in_gen!$C$44*-$C38) -> 0.0018 | AA38: =I38*(1+in_gen!$C$44*-$C38) -> 0.0024 | AB38: =J38*(1+in_gen!$C$44*-$C38) -> 0.000792 | AC38: =K38*(1+in_gen!$C$44*-$C38) -> 0.000792 | AD38: =L38*(1+in_gen!$C$44*-$C38) -> 0.0012
A39: solar_wave_loss | C39: 1 | D39: 0.015 | E39: 0.015 | F39: 0.02 | G39: 0.0075 | H39: 0.0075 | I39: 0.01 | J39: 0.0033 | K39: 0.0033 | L39: 0.005 | M39: =D39*(1+in_gen!$C$44*$C39) -> 0.0156 | N39: =E39*(1+in_gen!$C$44*$C39) -> 0.0156 | O39: =F39*(1+in_gen!$C$44*$C39) -> 0.0208 | P39: =G39*(1+in_gen!$C$44*$C39) -> 0.0078 | Q39: =H39*(1+in_gen!$C$44*$C39) -> 0.0078 | R39: =I39*(1+in_gen!$C$44*$C39) -> 0.0104 | S39: =J39*(1+in_gen!$C$44*$C39) -> 0.003432 | T39: =K39*(1+in_gen!$C$44*$C39) -> 0.003432 | U39: =L39*(1+in_gen!$C$44*$C39) -> 0.0052 | V39: =D39*(1+in_gen!$C$44*-$C39) -> 0.0144 | W39: =E39*(1+in_gen!$C$44*-$C39) -> 0.0144 | X39: =F39*(1+in_gen!$C$44*-$C39) -> 0.0192 | Y39: =G39*(1+in_gen!$C$44*-$C39) -> 0.0072 | Z39: =H39*(1+in_gen!$C$44*-$C39) -> 0.0072 | AA39: =I39*(1+in_gen!$C$44*-$C39) -> 0.0096 | AB39: =J39*(1+in_gen!$C$44*-$C39) -> 0.003168 | AC39: =K39*(1+in_gen!$C$44*-$C39) -> 0.003168 | AD39: =L39*(1+in_gen!$C$44*-$C39) -> 0.0048
A41: Energy (kWh)
A42: solar_production_yearly | C42: -1 | D42: 898 | E42: 898 | F42: 898 | G42: 927 | H42: 927 | I42: 927 | J42: 1306 | K42: 1306 | L42: 1306 | M42: =D42*(1+in_gen!$C$44*$C42) -> 862.08 | N42: =E42*(1+in_gen!$C$44*$C42) -> 862.08 | O42: =F42*(1+in_gen!$C$44*$C42) -> 862.08 | P42: =G42*(1+in_gen!$C$44*$C42) -> 889.92 | Q42: =H42*(1+in_gen!$C$44*$C42) -> 889.92 | R42: =I42*(1+in_gen!$C$44*$C42) -> 889.92 | S42: =J42*(1+in_gen!$C$44*$C42) -> 1253.76 | T42: =K42*(1+in_gen!$C$44*$C42) -> 1253.76 | U42: =L42*(1+in_gen!$C$44*$C42) -> 1253.76 | V42: =D42*(1+in_gen!$C$44*-$C42) -> 933.92 | W42: =E42*(1+in_gen!$C$44*-$C42) -> 933.92 | X42: =F42*(1+in_gen!$C$44*-$C42) -> 933.92 | Y42: =G42*(1+in_gen!$C$44*-$C42) -> 964.08 | Z42: =H42*(1+in_gen!$C$44*-$C42) -> 964.08 | AA42: =I42*(1+in_gen!$C$44*-$C42) -> 964.08 | AB42: =J42*(1+in_gen!$C$44*-$C42) -> 1358.24 | AC42: =K42*(1+in_gen!$C$44*-$C42) -> 1358.24 | AD42: =L42*(1+in_gen!$C$44*-$C42) -> 1358.24

Sheet in_gen
A1: Parameter | B1: Unit | C1: Value | D1: Dir | E1: Pes | F1: Opt | G1: Comment
A2: Cost (€)
A3: solar_panel_prod_workhours_cost_per_hour | B3: € / h | C3: 40 | D3: 1 | E3: =$C3*(1+$C$44*D3) -> 41.6 | F3: =$C3*(1+$C$44*-D3) -> 38.4 | G3: Cost per hour for workers assembly of floating solar panels.
A4: solar_panel_prod_material_costs | B4: € / kW | C4: 250 | D4: 1 | E4: =$C4*(1+$C$44*D4) -> 260 | F4: =$C4*(1+$C$44*-D4) -> 240 | G4: Aggregate material costs per kilowatt of nominal power, including the solar panel, polyurethane, pvc pipe, etc.
A5: solar_panel_prod_other_costs | B5: € / kW | C5: 90 | D5: 1 | E5: =$C5*(1+$C$44*D5) -> 93.6 | F5: =$C5*(1+$C$44*-D5) -> 86.4 | G5: Packaging, insurance, rent, energy, etc, per kilowatt of nominal power.
A6: container_transport_cost_road | B6: €/km per container | C6: 2 | D6: 1 | E6: =$C6*(1+$C$44*D6) -> 2.08 | F6: =$C6*(1+$C$44*-D6) -> 1.92 | G6: Standard European trucking rates for containers.
A7: container_transport_cost_sea | B7: €/km per container | C7: 5 | D7: 1 | E7: =$C7*(1+$C$44*D7) -> 5.2 | F7: =$C7*(1+$C$44*-D7) -> 4.8 | G7: Short-sea shipping rates from Maersk and MSC.
A8: dc_cable_cost_per_m | B8: €/m | C8: 2 | D8: 1 | E8: =$C8*(1+$C$44*D8) -> 2.08 | F8: =$C8*(1+$C$44*-D8) -> 1.92 | G8: Standard PV DC cables (e.g., 6mm² or 10mm² XLPE-insulated).
A9: ac_cable_cost_per_m | B9: €/m | C9: 80 | D9: 1 | E9: =$C9*(1+$C$44*D9) -> 83.2 | F9: =$C9*(1+$C$44*-D9) -> 76.8 | G9: Pricing for 33 kV medium-voltage aluminum cables.
A10: mv_floating_cable_cost_per_m | B10: €/m | C10: 95 | D10: 1 | E10: =$C10*(1+$C$44*D10) -> 98.8 | F10: =$C10*(1+$C$44*-D10) -> 91.2 | G10: Marine-certified floating cables like Prysmian FlexoMarine.
A11: mv_submarine_cable_cost_per_m | B11: €/m | C11: 150 | D11: 1 | E11: =$C11*(1+$C$44*D11) -> 156 | F11: =$C11*(1+$C$44*-D11) -> 144 | G11: Pricing for 33 kV offshore submarine cables.
A12: cable_installation_cost_per_m | B12: €/m | C12: 50 | D12: 1 | E12: =$C12*(1+$C$44*D12) -> 52 | F12: =$C12*(1+$C$44*-D12) -> 48 | G12: Typical cost for ROV-assisted submarine cable installation.
A13: scada_ppc | B13: € | C13: 12000 | D13: 1 | E13: =$C13*(1+$C$44*D13) -> 12480 | F13: =$C13*(1+$C$44*-D13) -> 11520 | G13: Power Plant Controller required for grid compliance
A14: scada_sems | B14: € | C14: 5000 | D14: 1 | E14: =$C14*(1+$C$44*D14) -> 5200 | F14: =$C14*(1+$C$44*-D14) -> 4800 | G14: Optional if cloud-only is used
... A25: anchor_chain_cost_per_t | B25: €/t | C25: 3000 | D25: 1 | E25: =$C25*(1+$C$44*D25) -> 3120 | F25: =$C25*(1+$C$44*-D25) -> 2880 | G25: Anchor chain cost per ton. Higher requirements than anchors, more expensive
A26: solar_energy_target_price | B26: €/kWh | C26: 0.12 | D26: 1 | E26: =$C26*(1+$C$44*D26) -> 0.1248 | F26: =$C26*(1+$C$44*-D26) -> 0.1152
A28: Count (unit)
A29: panels_per_container | B29: panels | C29: 400 | D29: 0 | E29: =$C29*(1+$C$44*D29) -> 400 | F29: =$C29*(1+$C$44*-D29) -> 400 | G29: A 40-ft high-cube container typically holds 380–420 panels.
A30: solar_lifetimes_per_wavebreaker_lifetime | C30: 2 | D30: 0 | E30: =$C30*(1+$C$44*D30) -> 2 | F30: =$C30*(1+$C$44*-D30) -> 2 | G30: How many solar lifetimes the wavebreaker lasts (i.e 50 years compared to 25 years for solar)
A32: Distance (m)
A33: dc_cable_per_panel | B33: m/panel | C33: 4 | D33: 0 | E33: =$C33*(1+$C$44*D33) -> 4 | F33: =$C33*(1+$C$44*-D33) -> 4 | G33: Based on average cabling per panel in utility solar installations
A34: ac_cable_length | B34: m | C34: 30 | D34: 0 | E34: =$C34*(1+$C$44*D34) -> 30 | F34: =$C34*(1+$C$44*-D34) -> 30 | G34: Estimated short connection between inverters and transformers.
A35: mv_floating_cable_length | B35: m | C35: 300 | D35: 0 | E35: =$C35*(1+$C$44*D35) -> 300 | F35: =$C35*(1+$C$44*-D35) -> 300 | G35: Bridges the distance between floating transformers and substation.
A36: solar_panel_width | B36: mm | C36: 1303 | D36: 0 | E36: =$C36*(1+$C$44*D36) -> 1303 | F36: =$C36*(1+$C$44*-D36) -> 1303 | G36: Width of the solar panel, excluding connecting joint
A37: solar_panel_length | B37: mm | C37: 2384 | D37: 0 | E37: =$C37*(1+$C$44*D37) -> 2384 | F37: =$C37*(1+$C$44*-D37) -> 2384 | G37: Length of the solar panel, excluding connecting joint
A38: solar_panel_hinge_length | B38: mm | C38: 150 | D38: 0 | E38: =$C38*(1+$C$44*D38) -> 150 | F38: =$C38*(1+$C$44*-D38) -> 150 | G38: Length of the hinge connecting the solar panels
A39: pontoon_width | B39: m | C39: 5 | D39: 0 | E39: =$C39*(1+$C$44*D39) -> 5 | F39: =$C39*(1+$C$44*-D39) -> 5 | G39: Width of pontoon, used for calculating space not usable for solar panels.
A41: Percentages (%)
A42: discount_rate | B42: % | C42: 0.085 | D42: 1 | E42: =$C42*(1+$C$44*D42) -> 0.0884 | F42: =$C42*(1+$C$44*-D42) -> 0.0816 | G42: Cost of lending money / alternative investment rate
A43: solar_extra_production_from_cooling | B43: % | C43: 0.08 | D43: -1 | E43: =$C43*(1+$C$44*D43) -> 0.0768 | F43: =$C43*(1+$C$44*-D43) -> 0.0832 | G43: Water has better heat conductivity than air. But as shown in the temperatures sheet, air temps are usually a bit cooler than the water for most locations. We therefore apply a flat cooling factor based on earlier tests for Sunlit Sea's product.
A44: sensitivity_margin | B44: % | C44: 0.04 | D44: 0 | E44: =$C44*(1+$C$44*D44) -> 0.04 | F44: =$C44*(1+$C$44*-D44) -> 0.04
A46: Power (W)
A47: solar_panel_power | B47: W per panel | C47: 730 | D47: 0 | E47: =$C47*(1+$C$44*D47) -> 730 | F47: =$C47*(1+$C$44*-D47) -> 730 | G47: Newer high-efficiency bifacial panels offer 650–750 W.
A49: Time (h / d / y)
A50: solar_panel_prod_workhours_per_kw | B50: h / kW | C50: 4 | D50: 1 | E50: =$C50*(1+$C$44*D50) -> 4.16 | F50: =$C50*(1+$C$44*-D50) -> 3.84 | G50: Production workhours to produce 1 kilowatt of nominal power. With a panel of 0.67 W that equals 1.493 panels
A51: solar_lifetime | B51: y | C51: 25 | D51: -1 | E51: =$C51*(1+$C$44*D51) -> 24 | F51: =$C51*(1+$C$44*-D51) -> 26 | G51: Lifetime for marine solar panels

Sheet inter_gen
A1: Parameter | B1: Unit | C1: Value | E1: Pes | F1: Opt | G1: Comment | H1: Formula
A2: total_ac_cable_cost | B2: € | C2: =in_gen!C9 * in_gen!C34 -> 2400 | E2: =in_gen!E9 * in_gen!E34 -> 2496 | F2: =in_gen!F9 * in_gen!F34 -> 2304 | H2: =in_gen!A9 & " * " & in_gen!A34 -> ac_cable_cost_per_m * ac_cable_length
A3: total_mv_floating_cable_cost | B3: € | C3: =in_gen!C10 * in_gen!C35 -> 28500 | E3: =in_gen!E10 * in_gen!E35 -> 29640 | F3: =in_gen!F10 * in_gen!F35 -> 27360 | H3: =in_gen!A10 & " * " & in_gen!A35 -> mv_floating_cable_cost_per_m * mv_floating_cable_length
A4: solar_panel_cost | B4: € / kW | C4: =in_gen!C50 * in_gen!C3 + in_gen!C4 + in_gen!C5 -> 500 | E4: =in_gen!E50 * in_gen!E3 + in_gen!E4 + in_gen!E5 -> 526.656 | F4: =in_gen!F50 * in_gen!F3 + in_gen!F4 + in_gen!F5 -> 473.856 | G4: Sunlit Sea floating solar panels market price. See own calculation | H4: =in_gen!A50 & " * " & in_gen!A3 & " + " & in_gen!A4 & " + " & in_gen!A5 -> solar_panel_prod_workhours_per_kw * solar_panel_prod_workhours_cost_per_hour + solar_panel_prod_material_costs + solar_panel_prod_other_costs
A5: scada_system | B5: € | C5: =in_gen!C13+in_gen!C14+in_gen!C15+in_gen!C16+in_gen!C17+in_gen!C18+in_gen!C19+in_gen!C20+in_gen!C21 -> 39000 | E5: =in_gen!E13+in_gen!E14+in_gen!E15+in_gen!E16+in_gen!E17+in_gen!E18+in_gen!E19+in_gen!E20+in_gen!E21 -> 40560 | F5: =in_gen!F13+in_gen!F14+in_gen!F15+in_gen!F16+in_gen!F17+in_gen!F18+in_gen!F19+in_gen!F20+in_gen!F21 -> 37440 | H5: =in_gen!A13 & " + " & in_gen!A14 & " + " & in_gen!A15 & " + " & in_gen!A16 & " + " & in_gen!A17 & " + " & in_gen!A18 & " + " & in_gen!A19 & " + " & in_gen!A20 & " + " & in_gen!A21 -> scada_ppc + scada_sems + scada_weather_station + scada_smart_energy_meter + scada_gateway_rtu + scada_switch_fiber + scada_local_hmi + scada_license_config + scada_cabling_racks_power_backup

Sheet out_loc
A1: Parameter | B1: Unit | C1: Comment | D1: n_2 | E1: n_25 | F1: n_10 | G1: b_2 | H1: b_25 | I1: b_10 | J1: m_2 | K1: m_25 | L1: m_10 | M1: =D1&"_pes" -> n_2_pes | N1: =E1&"_pes" -> n_25_pes | O1: =F1&"_pes" -> n_10_pes | P1: =G1&"_pes" -> b_2_pes | Q1: =H1&"_pes" -> b_25_pes | R1: =I1&"_pes" -> b_10_pes | S1: =J1&"_pes" -> m_2_pes | T1: =K1&"_pes" -> m_25_pes | U1: =L1&"_pes" -> m_10_pes | V1: =D1&"_opt" -> n_2_opt | W1: =E1&"_opt" -> n_25_opt | X1: =F1&"_opt" -> n_10_opt | Y1: =G1&"_opt" -> b_2_opt | Z1: =H1&"_opt" -> b_25_opt | AA1: =I1&"_opt" -> b_10_opt | AB1: =J1&"_opt" -> m_2_opt | AC1: =K1&"_opt" -> m_25_opt | AD1: =L1&"_opt" -> m_10_opt
A2: solar_panels_per_matrix_width | B2: unit | D2: =FLOOR((in_loc!D$33*1000+in_gen!$C$38)/(in_gen!$C$36+in_gen!$C$38),1) -> 9 | E2: =FLOOR((in_loc!E$33*1000+in_gen!$C$38)/(in_gen!$C$36+in_gen!$C$38),1) -> 9 | F2: =FLOOR((in_loc!F$33*1000+in_gen!$C$38)/(in_gen!$C$36+in_gen!$C$38),1) -> 19 | G2: =FLOOR((in_loc!G$33*1000+in_gen!$C$38)/(in_gen!$C$36+in_gen!$C$38),1) -> 9 | H2: =FLOOR((in_loc!H$33*1000+in_gen!$C$38)/(in_gen!$C$36+in_gen!$C$38),1) -> 9 | I2: =FLOOR((in_loc!I$33*1000+in_gen!$C$38)/(in_gen!$C$36+in_gen!$C$38),1) -> 19 | J2: =FLOOR((in_loc!J$33*1000+in_gen!$C$38)/(in_gen!$C$36+in_gen!$C$38),1) -> 9 | K2: =FLOOR((in_loc!K$33*1000+in_gen!$C$38)/(in_gen!$C$36+in_gen!$C$38),1) -> 9 | L2: =FLOOR((in_loc!L$33*1000+in_gen!$C$38)/(in_gen!$C$36+in_gen!$C$38),1) -> 19 | M2: =FLOOR((in_loc!M$33*1000+in_gen!$C$38)/(in_gen!$E$36+in_gen!$E$38),1) -> 9 | N2: =FLOOR((in_loc!N$33*1000+in_gen!$C$38)/(in_gen!$E$36+in_gen!$E$38),1) -> 9 | O2: =FLOOR((in_loc!O$33*1000+in_gen!$C$38)/(in_gen!$E$36+in_gen!$E$38),1) -> 19 | P2: =FLOOR((in_loc!P$33*1000+in_gen!$C$38)/(in_gen!$E$36+in_gen!$E$38),1) -> 9 | Q2: =FLOOR((in_loc!Q$33*1000+in_gen!$C$38)/(in_gen!$E$36+in_gen!$E$38),1) -> 9 | R2: =FLOOR((in_loc!R$33*1000+in_gen!$C$38)/(in_gen!$E$36+in_gen!$E$38),1) -> 19 | S2: =FLOOR((in_loc!S$33*1000+in_gen!$C$38)/(in_gen!$E$36+in_gen!$E$38),1) -> 9 | T2: =FLOOR((in_loc!T$33*1000+in_gen!$C$38)/(in_gen!$E$36+in_gen!$E$38),1) -> 9 | U2: =FLOOR((in_loc!U$33*1000+in_gen!$C$38)/(in_gen!$E$36+in_gen!$E$38),1) -> 19 | V2: =FLOOR((in_loc!V$33*1000+in_gen!$F$38)/(in_gen!$F$36+in_gen!$F$38),1) -> 9 | W2: =FLOOR((in_loc!W$33*1000+in_gen!$F$38)/(in_gen!$F$36+in_gen!$F$38),1) -> 9 | X2: =FLOOR((in_loc!X$33*1000+in_gen!$F$38)/(in_gen!$F$36+in_gen!$F$38),1) -> 19 | Y2: =FLOOR((in_loc!Y$33*1000+in_gen!$F$38)/(in_gen!$F$36+in_gen!$F$38),1) -> 9 | Z2: =FLOOR((in_loc!Z$33*1000+in_gen!$F$38)/(in_gen!$F$36+in_gen!$F$38),1) -> 9 | AA2: =FLOOR((in_loc!AA$33*1000+in_gen!$F$38)/(in_gen!$F$36+in_gen!$F$38),1) -> 19 | AB2: =FLOOR((in_loc!AB$33*1000+in_gen!$F$38)/(in_gen!$F$36+in_gen!$F$38),1) -> 9 | AC2: =FLOOR((in_loc!AC$33*1000+in_gen!$F$38)/(in_gen!$F$36+in_gen!$F$38),1) -> 9 | AD2: =FLOOR((in_loc!AD$33*1000+in_gen!$F$38)/(in_gen!$F$36+in_gen!$F$38),1) -> 19
A3: solar_panels_per_matrix_length | B3: unit | D3: =FLOOR((in_loc!D$33*1000+in_gen!$C$38)/(in_gen!$C$37+in_gen!$C$38),1) -> 5 | E3: =FLOOR((in_loc!E$33*1000+in_gen!$C$38)/(in_gen!$C$37+in_gen!$C$38),1) -> 5 | F3: =FLOOR((in_loc!F$33*1000+in_gen!$C$38)/(in_gen!$C$37+in_gen!$C$38),1) -> 11 | G3: =FLOOR((in_loc!G$33*1000+in_gen!$C$38)/(in_gen!$C$37+in_gen!$C$38),1) -> 5 | H3: =FLOOR((in_loc!H$33*1000+in_gen!$C$38)/(in_gen!$C$37+in_gen!$C$38),1) -> 5 | I3: =FLOOR((in_loc!I$33*1000+in_gen!$C$38)/(in_gen!$C$37+in_gen!$C$38),1) -> 11 | J3: =FLOOR((in_loc!J$33*1000+in_gen!$C$38)/(in_gen!$C$37+in_gen!$C$38),1) -> 5 | K3: =FLOOR((in_loc!K$33*1000+in_gen!$C$38)/(in_gen!$C$37+in_gen!$C$38),1) -> 5 | L3: =FLOOR((in_loc!L$33*1000+in_gen!$C$38)/(in_gen!$C$37+in_gen!$C$38),1) -> 11 | M3: =FLOOR((in_loc!M$33*1000+in_gen!$E$38)/(in_gen!$E$37+in_gen!$E$38),1) -> 5 | N3: =FLOOR((in_loc!N$33*1000+in_gen!$E$38)/(in_gen!$E$37+in_gen!$E$38),1) -> 5 | O3: =FLOOR((in_loc!O$33*1000+in_gen!$E$38)/(in_gen!$E$37+in_gen!$E$38),1) -> 11 | P3: =FLOOR((in_loc!P$33*1000+in_gen!$E$38)/(in_gen!$E$37+in_gen!$E$38),1) -> 5 | Q3: =FLOOR((in_loc!Q$33*1000+in_gen!$E$38)/(in_gen!$E$37+in_gen!$E$38),1) -> 5 | R3: =FLOOR((in_loc!R$33*1000+in_gen!$E$38)/(in_gen!$E$37+in_gen!$E$38),1) -> 11 | S3: =FLOOR((in_loc!S$33*1000+in_gen!$E$38)/(in_gen!$E$37+in_gen!$E$38),1) -> 5 | T3: =FLOOR((in_loc!T$33*1000+in_gen!$E$38)/(in_gen!$E$37+in_gen!$E$38),1) -> 5 | U3: =FLOOR((in_loc!U$33*1000+in_gen!$E$38)/(in_gen!$E$37+in_gen!$E$38),1) -> 11 | V3: =FLOOR((in_loc!V$33*1000+in_gen!$F$38)/(in_gen!$F$37+in_gen!$F$38),1) -> 5 | W3: =FLOOR((in_loc!W$33*1000+in_gen!$F$38)/(in_gen!$F$37+in_gen!$F$38),1) -> 5 | X3: =FLOOR((in_loc!X$33*1000+in_gen!$F$38)/(in_gen!$F$37+in_gen!$F$38),1) -> 11 | Y3: =FLOOR((in_loc!Y$33*1000+in_gen!$F$38)/(in_gen!$F$37+in_gen!$F$38),1) -> 5 | Z3: =FLOOR((in_loc!Z$33*1000+in_gen!$F$38)/(in_gen!$F$37+in_gen!$F$38),1) -> 5 | AA3: =FLOOR((in_loc!AA$33*1000+in_gen!$F$38)/(in_gen!$F$37+in_gen!$F$38),1) -> 11 | AB3: =FLOOR((in_loc!AB$33*1000+in_gen!$F$38)/(in_gen!$F$37+in_gen!$F$38),1) -> 5 | AC3: =FLOOR((in_loc!AC$33*1000+in_gen!$F$38)/(in_gen!$F$37+in_gen!$F$38),1) -> 5 | AD3: =FLOOR((in_loc!AD$33*1000+in_gen!$F$38)/(in_gen!$F$37+in_gen!$F$38),1) -> 11
A4: solar_panels_per_matrix | B4: unit | D4: =D$2*D$3 -> 45 | E4: =E$2*E$3 -> 45 | F4: =F$2*F$3 -> 209 | G4: =G$2*G$3 -> 45 | H4: =H$2*H$3 -> 45 | I4: =I$2*I$3 -> 209 | J4: =J$2*J$3 -> 45 | K4: =K$2*K$3 -> 45 | ... AD4: =AD$2*AD$3 -> 209
A5: solar_radius | B5: m | D5: =CEILING(SQRT(1+D$7^2)*in_loc!D$33,1) +in_gen!$C$39/2 -> 74.5 | E5: =CEILING(SQRT(1+E$7^2)*in_loc!E$33,1) +in_gen!$C$39/2 -> 74.5 | F5: =CEILING(SQRT(1+F$7^2)*in_loc!F$33,1) +in_gen!$C$39/2 -> 145.5 | G5: =CEILING(SQRT(1+G$7^2)*in_loc!G$33,1) +in_gen!$C$39/2 -> 74.5 | H5: =CEILING(SQRT(1+H$7^2)*in_loc!H$33,1) +in_gen!$C$39/2 -> 74.5 | I5: =CEILING(SQRT(1+I$7^2)*in_loc!I$33,1) +in_gen!$C$39/2 -> 145.5 | J5: =CEILING(SQRT(1+J$7^2)*in_loc!J$33,1) +in_gen!$C$39/2 -> 74.5 | K5: =CEILING(SQRT(1+K$7^2)*in_loc!K$33,1) +in_gen!$C$39/2 -> 74.5 | L5: =CEILING(SQRT(1+L$7^2)*in_loc!L$33,1) +in_gen!$C$39/2 -> 145.5 | M5: =CEILING(SQRT(1+M$7^2)*in_loc!M$33,1) +in_gen!$E$39/2 -> 74.5 | N5: =CEILING(SQRT(1+N$7^2)*in_loc!N$33,1) +in_gen!$E$39/2 -> 74.5 | O5: =CEILING(SQRT(1+O$7^2)*in_loc!O$33,1) +in_gen!$E$39/2 -> 145.5 | P5: =CEILING(SQRT(1+P$7^2)*in_loc!P$33,1) +in_gen!$E$39/2 -> 74.5 | Q5: =CEILING(SQRT(1+Q$7^2)*in_loc!Q$33,1) +in_gen!$E$39/2 -> 74.5 | R5: =CEILING(SQRT(1+R$7^2)*in_loc!R$33,1) +in_gen!$E$39/2 -> 145.5 | S5: =CEILING(SQRT(1+S$7^2)*in_loc!S$33,1) +in_gen!$E$39/2 -> 74.5 | T5: =CEILING(SQRT(1+T$7^2)*in_loc!T$33,1) +in_gen!$E$39/2 -> 74.5 | U5: =CEILING(SQRT(1+U$7^2)*in_loc!U$33,1) +in_gen!$E$39/2 -> 145.5 | V5: =CEILING(SQRT(1+V$7^2)*in_loc!V$33,1) +in_gen!$F$39/2 -> 74.5 | W5: =CEILING(SQRT(1+W$7^2)*in_loc!W$33,1) +in_gen!$F$39/2 -> 74.5 | X5: =CEILING(SQRT(1+X$7^2)*in_loc!X$33,1) +in_gen!$F$39/2 -> 145.5 | Y5: =CEILING(SQRT(1+Y$7^2)*in_loc!Y$33,1) +in_gen!$F$39/2 -> 74.5 | Z5: =CEILING(SQRT(1+Z$7^2)*in_loc!Z$33,1) +in_gen!$F$39/2 -> 74.5 | AA5: =CEILING(SQRT(1+AA$7^2)*in_loc!AA$33,1) +in_gen!$F$39/2 -> 145.5 | AB5: =CEILING(SQRT(1+AB$7^2)*in_loc!AB$33,1) +in_gen!$F$39/2 -> 74.5 | AC5: =CEILING(SQRT(1+AC$7^2)*in_loc!AC$33,1) +in_gen!$F$39/2 -> 74.5 | AD5: =CEILING(SQRT(1+AD$7^2)*in_loc!AD$33,1) +in_gen!$F$39/2 -> 145.5
A6: total_solar_panels | B6: unit | D6: =D$4*in_loc!D$21*4 -> 3060 | E6: =E$4*in_loc!E$21*4 -> 3060 | F6: =F$4*in_loc!F$21*4 -> 14212 | G6: =G$4*in_loc!G$21*4 -> 3060 | H6: =H$4*in_loc!H$21*4 -> 3060 | I6: =I$4*in_loc!I$21*4 -> 14212 | J6: =J$4*in_loc!J$21*4 -> 3060 | K6: =K$4*in_loc!K$21*4 -> 3060 | ... AD6: =AD$4*in_loc!AD$21*4 -> 14212
A7: solar_matrices_along_radii | B7: unit | D7: =CEILING(SQRT(in_loc!D$21),1) -> 5 | E7: =CEILING(SQRT(in_loc!E$21),1) -> 5 | F7: =CEILING(SQRT(in_loc!F$21),1) -> 5 | G7: =CEILING(SQRT(in_loc!G$21),1) -> 5 | H7: =CEILING(SQRT(in_loc!H$21),1) -> 5 | I7: =CEILING(SQRT(in_loc!I$21),1) -> 5 | J7: =CEILING(SQRT(in_loc!J$21),1) -> 5 | K7: =CEILING(SQRT(in_loc!K$21),1) -> 5 | ... AD7: =CEILING(SQRT(in_loc!AD$21),1) -> 5
A8: total_dc_cable_cost | B8: € | D8: =in_gen!$C$8*in_gen!$C$33*D$6 -> 24480 | E8: =in_gen!$C$8*in_gen!$C$33*E$6 -> 24480 | F8: =in_gen!$C$8*in_gen!$C$33*F$6 -> 113696 | G8: =in_gen!$C$8*in_gen!$C$33*G$6 -> 24480 | H8: =in_gen!$C$8*in_gen!$C$33*H$6 -> 24480 | I8: =in_gen!$C$8*in_gen!$C$33*I$6 -> 113696 | J8: =in_gen!$C$8*in_gen!$C$33*J$6 -> 24480 | K8: =in_gen!$C$8*in_gen!$C$33*K$6 -> 24480 | L8: =in_gen!$C$8*in_gen!$C$33*L$6 -> 113696 | M8: =in_gen!$E$8*in_gen!$E$33*M$6 -> 25459.2 | N8: =in_gen!$E$8*in_gen!$E$33*N$6 -> 25459.2 | O8: =in_gen!$E$8*in_gen!$E$33*O$6 -> 118243.84 | P8: =in_gen!$E$8*in_gen!$E$33*P$6 -> 25459.2 | Q8: =in_gen!$E$8*in_gen!$E$33*Q$6 -> 25459.2 | R8: =in_gen!$E$8*in_gen!$E$33*R$6 -> 118243.84 | S8: =in_gen!$E$8*in_gen!$E$33*S$6 -> 25459.2 | T8: =in_gen!$E$8*in_gen!$E$33*T$6 -> 25459.2 | U8: =in_gen!$E$8*in_gen!$E$33*U$6 -> 118243.84 | V8: =in_gen!$F$8*in_gen!$F$33*V$6 -> 23500.8 | W8: =in_gen!$F$8*in_gen!$F$33*W$6 -> 23500.8 | X8: =in_gen!$F$8*in_gen!$F$33*X$6 -> 109148.16 | Y8: =in_gen!$F$8*in_gen!$F$33*Y$6 -> 23500.8 | Z8: =in_gen!$F$8*in_gen!$F$33*Z$6 -> 23500.8 | AA8: =in_gen!$F$8*in_gen!$F$33*AA$6 -> 109148.16 | AB8: =in_gen!$F$8*in_gen!$F$33*AB$6 -> 23500.8 | AC8: =in_gen!$F$8*in_gen!$F$33*AC$6 -> 23500.8 | AD8: =in_gen!$F$8*in_gen!$F$33*AD$6 -> 109148.16
A9: total_solar_power | B9: kW | D9: =D$6*in_gen!$C$47/1000 -> 2233.8 | E9: =E$6*in_gen!$C$47/1000 -> 2233.8 | F9: =F$6*in_gen!$C$47/1000 -> 10374.76 | G9: =G$6*in_gen!$C$47/1000 -> 2233.8 | H9: =H$6*in_gen!$C$47/1000 -> 2233.8 | I9: =I$6*in_gen!$C$47/1000 -> 10374.76 | J9: =J$6*in_gen!$C$47/1000 -> 2233.8 | K9: =K$6*in_gen!$C$47/1000 -> 2233.8 | L9: =L$6*in_gen!$C$47/1000 -> 10374.76 | M9: =M$6*in_gen!$E$47/1000 -> 2233.8 | N9: =N$6*in_gen!$E$47/1000 -> 2233.8 | O9: =O$6*in_gen!$E$47/1000 -> 10374.76 | P9: =P$6*in_gen!$E$47/1000 -> 2233.8 | Q9: =Q$6*in_gen!$E$47/1000 -> 2233.8 | R9: =R$6*in_gen!$E$47/1000 -> 10374.76 | S9: =S$6*in_gen!$E$47/1000 -> 2233.8 | T9: =T$6*in_gen!$E$47/1000 -> 2233.8 | U9: =U$6*in_gen!$E$47/1000 -> 10374.76 | V9: =V$6*in_gen!$F$47/1000 -> 2233.8 | W9: =W$6*in_gen!$F$47/1000 -> 2233.8 | X9: =X$6*in_gen!$F$47/1000 -> 10374.76 | Y9: =Y$6*in_gen!$F$47/1000 -> 2233.8 | Z9: =Z$6*in_gen!$F$47/1000 -> 2233.8 | AA9: =AA$6*in_gen!$F$47/1000 -> 10374.76 | AB9: =AB$6*in_gen!$F$47/1000 -> 2233.8 | AC9: =AC$6*in_gen!$F$47/1000 -> 2233.8 | AD9: =AD$6*in_gen!$F$47/1000 -> 10374.76
A10: solar_container_count | B10: unit | D10: =CEILING(D$6/in_gen!$C$29,1) -> 8 | E10: =CEILING(E$6/in_gen!$C$29,1) -> 8 | F10: =CEILING(F$6/in_gen!$C$29,1) -> 36 | G10: =CEILING(G$6/in_gen!$C$29,1) -> 8 | H10: =CEILING(H$6/in_gen!$C$29,1) -> 8 | I10: =CEILING(I$6/in_gen!$C$29,1) -> 36 | J10: =CEILING(J$6/in_gen!$C$29,1) -> 8 | K10: =CEILING(K$6/in_gen!$C$29,1) -> 8 | L10: =CEILING(L$6/in_gen!$C$29,1) -> 36 | M10: =CEILING(M$6/in_gen!$E$29,1) -> 8 | N10: =CEILING(N$6/in_gen!$E$29,1) -> 8 | O10: =CEILING(O$6/in_gen!$E$29,1) -> 36 | P10: =CEILING(P$6/in_gen!$E$29,1) -> 8 | Q10: =CEILING(Q$6/in_gen!$E$29,1) -> 8 | R10: =CEILING(R$6/in_gen!$E$29,1) -> 36 | S10: =CEILING(S$6/in_gen!$E$29,1) -> 8 | T10: =CEILING(T$6/in_gen!$E$29,1) -> 8 | U10: =CEILING(U$6/in_gen!$E$29,1) -> 36 | V10: =CEILING(V$6/in_gen!$F$29,1) -> 8 | W10: =CEILING(W$6/in_gen!$F$29,1) -> 8 | X10: =CEILING(X$6/in_gen!$F$29,1) -> 36 | Y10: =CEILING(Y$6/in_gen!$F$29,1) -> 8 | Z10: =CEILING(Z$6/in_gen!$F$29,1) -> 8 | AA10: =CEILING(AA$6/in_gen!$F$29,1) -> 36 | AB10: =CEILING(AB$6/in_gen!$F$29,1) -> 8 | AC10: =CEILING(AC$6/in_gen!$F$29,1) -> 8 | AD10: =CEILING(AD$6/in_gen!$F$29,1) -> 36
A11: total_mv_submarine_cable_cost | B11: € | D11: =(in_gen!$C$11+in_gen!$C$12)*in_loc!D$34 -> 34000000 | E11: =(in_gen!$C$11+in_gen!$C$12)*in_loc!E$34 -> 34000000 | F11: =(in_gen!$C$11+in_gen!$C$12)*in_loc!F$34 -> 34000000 | G11: =(in_gen!$C$11+in_gen!$C$12)*in_loc!G$34 -> 6000000 | H11: =(in_gen!$C$11+in_gen!$C$12)*in_loc!H$34 -> 6000000 | I11: =(in_gen!$C$11+in_gen!$C$12)*in_loc!I$34 -> 6000000 | J11: =(in_gen!$C$11+in_gen!$C$12)*in_loc!J$34 -> 2200000 | K11: =(in_gen!$C$11+in_gen!$C$12)*in_loc!K$34 -> 2200000 | L11: =(in_gen!$C$11+in_gen!$C$12)*in_loc!L$34 -> 2200000 | M11: =(in_gen!$E$11+in_gen!$E$12)*in_loc!M$34 -> 35360000 | N11: =(in_gen!$E$11+in_gen!$E$12)*in_loc!N$34 -> 35360000 | O11: =(in_gen!$E$11+in_gen!$E$12)*in_loc!O$34 -> 35360000 | P11: =(in_gen!$E$11+in_gen!$E$12)*in_loc!P$34 -> 6240000 | Q11: =(in_gen!$E$11+in_gen!$E$12)*in_loc!Q$34 -> 6240000 | R11: =(in_gen!$E$11+in_gen!$E$12)*in_loc!R$34 -> 6240000 | S11: =(in_gen!$E$11+in_gen!$E$12)*in_loc!S$34 -> 2288000 | T11: =(in_gen!$E$11+in_gen!$E$12)*in_loc!T$34 -> 2288000 | U11: =(in_gen!$E$11+in_gen!$E$12)*in_loc!U$34 -> 2288000 | V11: =(in_gen!$F$11+in_gen!$F$12)*in_loc!V$34 -> 32640000 | W11: =(in_gen!$F$11+in_gen!$F$12)*in_loc!W$34 -> 32640000 | X11: =(in_gen!$F$11+in_gen!$F$12)*in_loc!X$34 -> 32640000 | Y11: =(in_gen!$F$11+in_gen!$F$12)*in_loc!Y$34 -> 5760000 | Z11: =(in_gen!$F$11+in_gen!$F$12)*in_loc!Z$34 -> 5760000 | AA11: =(in_gen!$F$11+in_gen!$F$12)*in_loc!AA$34 -> 5760000 | AB11: =(in_gen!$F$11+in_gen!$F$12)*in_loc!AB$34 -> 2112000 | AC11: =(in_gen!$F$11+in_gen!$F$12)*in_loc!AC$34 -> 2112000 | AD11: =(in_gen!$F$11+in_gen!$F$12)*in_loc!AD$34 -> 2112000
A13: total_pvc_cost | B13: € | D13: =in_gen!$C$22*in_loc!D$27 -> 16728 | E13: =in_gen!$C$22*in_loc!E$27 -> 83640 | F13: =in_gen!$C$22*in_loc!F$27 -> 69987 | G13: =in_gen!$C$22*in_loc!G$27 -> 16728 | H13: =in_gen!$C$22*in_loc!H$27 -> 83640 | I13: =in_gen!$C$22*in_loc!I$27 -> 69987 | J13: =in_gen!$C$22*in_loc!J$27 -> 16728 | K13: =in_gen!$C$22*in_loc!K$27 -> 83640 | L13: =in_gen!$C$22*in_loc!L$27 -> 69987 | M13: =in_gen!$E$22*in_loc!M$27 -> 17397.12 | N13: =in_gen!$E$22*in_loc!N$27 -> 86985.6 | O13: =in_gen!$E$22*in_loc!O$27 -> 72786.48 | P13: =in_gen!$E$22*in_loc!P$27 -> 17397.12 | Q13: =in_gen!$E$22*in_loc!Q$27 -> 86985.6 | R13: =in_gen!$E$22*in_loc!R$27 -> 72786.48 | S13: =in_gen!$E$22*in_loc!S$27 -> 17397.12 | T13: =in_gen!$E$22*in_loc!T$27 -> 86985.6 | U13: =in_gen!$E$22*in_loc!U$27 -> 72786.48 | V13: =in_gen!$F$22*in_loc!V$27 -> 16058.88 | W13: =in_gen!$F$22*in_loc!W$27 -> 80294.4 | X13: =in_gen!$F$22*in_loc!X$27 -> 67187.52 | Y13: =in_gen!$F$22*in_loc!Y$27 -> 16058.88 | Z13: =in_gen!$F$22*in_loc!Z$27 -> 80294.4 | AA13: =in_gen!$F$22*in_loc!AA$27 -> 67187.52 | AB13: =in_gen!$F$22*in_loc!AB$27 -> 16058.88 | AC13: =in_gen!$F$22*in_loc!AC$27 -> 80294.4 | AD13: =in_gen!$F$22*in_loc!AD$27 -> 67187.52
A14: total_rope_cost | B14: € | D14: =in_gen!$C$23*in_loc!D$28 -> 2700 | E14: =in_gen!$C$23*in_loc!E$28 -> 13500 | F14: =in_gen!$C$23*in_loc!F$28 -> 12300 | G14: =in_gen!$C$23*in_loc!G$28 -> 2700 | H14: =in_gen!$C$23*in_loc!H$28 -> 13500 | I14: =in_gen!$C$23*in_loc!I$28 -> 12300 | J14: =in_gen!$C$23*in_loc!J$28 -> 2700 | K14: =in_gen!$C$23*in_loc!K$28 -> 13500 | L14: =in_gen!$C$23*in_loc!L$28 -> 12300 | M14: =in_gen!$E$23*in_loc!M$28 -> 2808 | N14: =in_gen!$E$23*in_loc!N$28 -> 14040 | O14: =in_gen!$E$23*in_loc!O$28 -> 12792 | P14: =in_gen!$E$23*in_loc!P$28 -> 2808 | Q14: =in_gen!$E$23*in_loc!Q$28 -> 14040 | R14: =in_gen!$E$23*in_loc!R$28 -> 12792 | S14: =in_gen!$E$23*in_loc!S$28 -> 2808 | T14: =in_gen!$E$23*in_loc!T$28 -> 14040 | U14: =in_gen!$E$23*in_loc!U$28 -> 12792 | V14: =in_gen!$F$23*in_loc!V$28 -> 2592 | W14: =in_gen!$F$23*in_loc!W$28 -> 12960 | X14: =in_gen!$F$23*in_loc!X$28 -> 11808 | Y14: =in_gen!$F$23*in_loc!Y$28 -> 2592 | Z14: =in_gen!$F$23*in_loc!Z$28 -> 12960 | AA14: =in_gen!$F$23*in_loc!AA$28 -> 11808 | AB14: =in_gen!$F$23*in_loc!AB$28 -> 2592 | AC14: =in_gen!$F$23*in_loc!AC$28 -> 12960 | AD14: =in_gen!$F$23*in_loc!AD$28 -> 11808
A15: solar_freight_cost | B15: € | D15: =in_loc!D$22*in_loc!D$35*D$10*VLOOKUP(D$13,freight!$A$2:$B999,2, TRUE) -> 3501.264 | E15: =in_loc!E$22*in_loc!E$35*E$10*VLOOKUP(E$13,freight!$A$2:$B999,2, TRUE) -> 17506.32 | F15: =in_loc!F$22*in_loc!F$35*F$10*VLOOKUP(F$13,freight!$A$2:$B999,2, TRUE) -> 15755.688 | G15: =in_loc!G$22*in_loc!G$35*G$10*VLOOKUP(G$13,freight!$A$2:$B999,2, TRUE) -> 5133.3048 | H15: =in_loc!H$22*in_loc!H$35*H$10*VLOOKUP(H$13,freight!$A$2:$B999,2, TRUE) -> 25666.524 | I15: =in_loc!I$22*in_loc!I$35*I$10*VLOOKUP(I$13,freight!$A$2:$B999,2, TRUE) -> 23099.872 | J15: =in_loc!J$22*in_loc!J$35*J$10*VLOOKUP(J$13,freight!$A$2:$B999,2, TRUE) -> 16382.527 | K15: =in_loc!K$22*in_loc!K$35*K$10*VLOOKUP(K$13,freight!$A$2:$B999,2, TRUE) -> 81912.636 | ... AD15: =in_loc!AD$22*in_loc!AD$35*AD$10*VLOOKUP(AD$13,freight!$A$2:$B999,2, TRUE) -> 73721.372
A16: total_pontoon_cost | B16: € | D16: {=INDEX(pontoons!$AA3:$AA999, MATCH(D$1, pontoons!$Z3:$Z999, 0))} -> 678095.6 | E16: {=INDEX(pontoons!$AA3:$AA999, MATCH(E$1, pontoons!$Z3:$Z999, 0))} -> 3390478 | F16: {=INDEX(pontoons!$AA3:$AA999, MATCH(F$1, pontoons!$Z3:$Z999, 0))} -> 2118899 | G16: {=INDEX(pontoons!$AA3:$AA999, MATCH(G$1, pontoons!$Z3:$Z999, 0))} -> 678095.6 | H16: {=INDEX(pontoons!$AA3:$AA999, MATCH(H$1, pontoons!$Z3:$Z999, 0))} -> 3390478 | I16: {=INDEX(pontoons!$AA3:$AA999, MATCH(I$1, pontoons!$Z3:$Z999, 0))} -> 2118899 | J16: {=INDEX(pontoons!$AA3:$AA999, MATCH(J$1, pontoons!$Z3:$Z999, 0))} -> 678095.6 | K16: {=INDEX(pontoons!$AA3:$AA999, MATCH(K$1, pontoons!$Z3:$Z999, 0))} -> 3390478 | ... AD16: {=INDEX(pontoons!$AA3:$AA999, MATCH(AD$1, pontoons!$Z3:$Z999, 0))} -> 2034143
A17: total_cost_solar_panels | B17: € | D17: =in_loc!D$22*inter_gen!$C$4*D$9 -> 1116900 | E17: =in_loc!E$22*inter_gen!$C$4*E$9 -> 5584500 | F17: =in_loc!F$22*inter_gen!$C$4*F$9 -> 5187380 | G17: =in_loc!G$22*inter_gen!$C$4*G$9 -> 1116900 | H17: =in_loc!H$22*inter_gen!$C$4*H$9 -> 5584500 | I17: =in_loc!I$22*inter_gen!$C$4*I$9 -> 5187380 | J17: =in_loc!J$22*inter_gen!$C$4*J$9 -> 1116900 | K17: =in_loc!K$22*inter_gen!$C$4*K$9 -> 5584500 | L17: =in_loc!L$22*inter_gen!$C$4*L$9 -> 5187380 | M17: =in_loc!M$22*inter_gen!$F$4*M$9 -> 1058499.5 | N17: =in_loc!N$22*inter_gen!$F$4*N$9 -> 5292497.7 | O17: =in_loc!O$22*inter_gen!$F$4*O$9 -> 4916142.3 | P17: =in_loc!P$22*inter_gen!$F$4*P$9 -> 1058499.5 | Q17: =in_loc!Q$22*inter_gen!$F$4*Q$9 -> 5292497.7 | R17: =in_loc!R$22*inter_gen!$F$4*R$9 -> 4916142.3 | S17: =in_loc!S$22*inter_gen!$F$4*S$9 -> 1058499.5 | T17: =in_loc!T$22*inter_gen!$F$4*T$9 -> 5292497.7 | ... AD17: =in_loc!AD$22*inter_gen!$F$4*AD$9 -> 4916142.3
A18: total_cost_cabling_short_alternative | B18: € | D18: =in_loc!D$22*(D$8+inter_gen!$C$2+inter_gen!$C$3) -> 55380 | E18: =in_loc!E$22*(E$8+inter_gen!$C$2+inter_gen!$C$3) -> 276900 | F18: =in_loc!F$22*(F$8+inter_gen!$C$2+inter_gen!$C$3) -> 144596 | G18: =in_loc!G$22*(G$8+inter_gen!$C$2+inter_gen!$C$3) -> 55380 | H18: =in_loc!H$22*(H$8+inter_gen!$C$2+inter_gen!$C$3) -> 276900 | I18: =in_loc!I$22*(I$8+inter_gen!$C$2+inter_gen!$C$3) -> 144596 | J18: =in_loc!J$22*(J$8+inter_gen!$C$2+inter_gen!$C$3) -> 55380 | K18: =in_loc!K$22*(K$8+inter_gen!$C$2+inter_gen!$C$3) -> 276900 | L18: =in_loc!L$22*(L$8+inter_gen!$C$2+inter_gen!$C$3) -> 144596 | M18: =in_loc!M$22*(M$8+inter_gen!$F$2+inter_gen!$F$3) -> 55123.2 | N18: =in_loc!N$22*(N$8+inter_gen!$F$2+inter_gen!$F$3) -> 275616 | O18: =in_loc!O$22*(O$8+inter_gen!$F$2+inter_gen!$F$3) -> 147907.84 | P18: =in_loc!P$22*(P$8+inter_gen!$F$2+inter_gen!$F$3) -> 55123.2 | Q18: =in_loc!Q$22*(Q$8+inter_gen!$F$2+inter_gen!$F$3) -> 275616 | R18: =in_loc!R$22*(R$8+inter_gen!$F$2+inter_gen!$F$3) -> 147907.84 | S18: =in_loc!S$22*(S$8+inter_gen!$F$2+inter_gen!$F$3) -> 55123.2 | T18: =in_loc!T$22*(T$8+inter_gen!$F$2+inter_gen!$F$3) -> 275616 | ... AD18: =in_loc!AD$22*(AD$8+inter_gen!$F$2+inter_gen!$F$3) -> 138812.16
