Workbook

Sheet Summary
A1: Feature | B1: Priority | C1: Status | D1: Owner | E1: Time period | F1: Notes
A2: FP1: Produces power | B2: Prio 3 | C2: Not started
A3: FP2: is certified | B3: Prio 2 | C3: Not started
A4: FC1: Floats on water | B4: Prio 1 | C4: Not started
A5: FC2: Is water tight | B5: Prio 2 | C5: Not started
A6: FC3: Mechanically attached | B6: Prio 1 | C6: Not started
A7: FC4: Does not go submarining under stream exposure, 3 m/s | B7: Prio 3 | C7: Not started
A8: FC5: Feasible to change panel type, i.e from Chinese to US | B8: Prio 2 | C8: Not started
A9: FC6: Resists high wind | B9: Prio 3 | C9: Not started
A10: FC7: Resists waves up to 1.5 Hs | B10: Prio 3 | C10: Not started
A11: FC8: Cheap to produce, cheaper total cost to install than competitors | B11: Prio 1 | C11: Not started
A12: FC9: Grounding of the FPV unit | B12: Prio 2 | C12: Not started
A13: FS1: Can walk on it | B13: Prio 2 | C13: Not started
... A15: FS3: Fast to install | B15: Prio 3 | C15: Not started

Sheet Function - criteria - Solution
A1: Column 1 | B1: Names | C1: Functions | D1: Prio | E1: Criteria | F1: Solutions | G1: Comment
A2: FP1 | B2: Power production | C2: Produces power | D2: 3 | E2: Performance ratio (how much kWh per kWp), power density (kWp/sqm), soiling degree, cooling effect | F2: PV panel
A3: FP2 | B3: Certification | C3: is certified | D3: 2 | E3: Certification not broken by modification/assembly | F3: Supplied certified | G3: Check certification void conditions
A4: FC1 | B4: Buoyancy | C4: Floats on water | D4: 1 | E4: Sufficient Buoyancy of the float / panel / hinges
A5: FC2 | B5: Water protection | C5: Is water tight | D5: 2 | E5: Float must be water tight. minimize the degradation ratio and fault probability PV & electronics must be protected
A6: FC3 | B6: Mechnical performance | C6: Mechanically attached | D6: 1 | E6: Tensile strength, shear strength, compression strength, fatigue strength safety value pass. is about the interconnection between floats
A7: FC4 | B7: Submarining | C7: Does not go submarining under stream exposure, 3 m/s | D7: 3 | E7: resist 3m/s stream | F7: Outsource the study
A8: FC5 | B8: Interchageability | C8: Feasible to change panel type, i.e from Chinese to US | D8: 2 | E8: Keep design open to different standard size
A9: FC6 | B9: Wind resistance | C9: Resists high wind | D9: 3 | E9: we keep the profile low and no wind traps
A10: FC7 | B10: Wave resistance | C10: Resists waves up to 1.5 Hs | D10: 3 | E10: linked to the hinges and the strucutral integrity of the float | G10: Long term goal
A11: FC8 | B11: Cost efficiency | C11: Cheap to produce, cheaper total cost to install than competitors | D11: 1 | E11: As cheap or cheaper than competitors CAPEX wise (now 250€/kWp)
A12: FC9 | B12: Grounding system | C12: Grounding of the FPV unit | D12: 2 | E12: maintainable grouding system of the floating matrix
A13: FC10 | B13: PV attachment | C13: The PV needs to stick to the float | D13: 1 | E13: Must remained attached to the float, must allow for hinge to be attached to the FPV
A14: FC11 | B14: Mooring | C14: Should be moored safely | D14: 3
A15: FC12 | B15: Internal pressure control | C15: Internal pressure control | D15: 3 | E15: No buldging, continious bonding of components
A16: FS1 | B16: Walkability | C16: Can walk on it | D16: 2 | E16: Avoid microcrack when walking on it and float matrix must be stable
A17: FS2 | B17: Manufacturability | C17: Fast to produce, not necessarily mass producible | D17: 2 | E17: Must be possible to assemble in Askim and should be exportable to the US. Objective: 90 to 900 floats per weeks for 2 people
A18: FS3 | B18: Deployability | C18: Fast to install | D18: 3 | E18: plug and play electrically, objective: 20 kW installed per Man/hour, light FPV carried by 2 ppl, no tools

Sheet Roadmap
A1: REF NUMBER | B1: Priority | C1: Function | D1: Task | E1: Duration (person-weeks) | F1: Start Week | G1: End Week | H1: Task owner | I1: 1 | J1: 2 | K1: 3 | L1: 4 | M1: 5 | N1: 6 | O1: 7 | P1: 8 | Q1: 9 | R1: 10 | S1: 11 | T1: 12 | U1: 13 | V1: 14 | W1: 15 | X1: 16 | Y1: 17 | Z1: 18 | AA1: 19 | AB1: 20 | AC1: 21 | AD1: 22 | AE1: 23 | AF1: 24 | AG1: 25 | AH1: 26 | AI1: 27 | AJ1: 28 | AK1: 29 | AL1: 30 | AM1: 31 | AN1: 32 | AO1: 33 | AP1: 34 | AQ1: 35 | AR1: 36 | AS1: 37 | AT1: 38 | AU1: 39 | AV1: 40 | AW1: 41 | AX1: 42 | AY1: 43 | AZ1: 44 | BA1: 45 | BB1: 46 | BC1: 47 | BD1: 48 | BE1: 49
A2: FC1 | B2: 1 | C2: Buoyancy | D2: Single unit buoyancy | E2: 4 | F2: 1 | G2: 4 | H2: Team A | I2: {=IF((COLUMN(I2:BE2) - COLUMN($I$1) + 1 >= $F2:$F63) * (COLUMN(I2:BE2) - COLUMN($I$1) + 1 <= $G2:$G63), "x", "")} -> x | J2: x | K2: x | L2: x
A3: FC1 | B3: 1 | C3: Buoyancy | D3: Float | E3: 4 | F3: 3 | G3: 6 | H3: Team A | K3: x | L3: x | M3: x | N3: x
A4: FC1 | B4: 1 | C4: Buoyancy | D4: Floating hinge | E4: 3 | F4: 5 | G4: 7 | H4: Team A | M4: x | N4: x | O4: x
A5: FC1 | B5: 1 | C5: Buoyancy | D5: Using the PV+frame as a float | E5: 3 | F5: 6 | G5: 8 | H5: Team A | N5: x | O5: x | P5: x
A6: FC1 | B6: 1 | C6: Buoyancy | D6: 1 hydroformed trough, 2 HF troughs, with different infills | E6: 3 | F6: 7 | G6: 9 | H6: Team A | O6: x | P6: x | Q6: x
A7: FC1 | B7: 1 | C7: Buoyancy | D7: Multiple unit buoyancy | E7: 3 | F7: 8 | G7: 10 | H7: Team A | P7: x | Q7: x | R7: x
A8: FC1 | B8: 1 | C8: Buoyancy | D8: Structural integrity of the assembled matrix | E8: 2 | F8: 10 | G8: 11 | H8: Team A | R8: x | S8: x
A9: FC1 | B9: 1 | C9: Buoyancy | D9: Fender on the matrix edge | E9: 1 | F9: 11 | G9: 12 | H9: Team A | S9: x | T9: x
A11: FC3 | B11: 1 | C11: Mechanical performance | D11: Sketch | E11: 4 | F11: 1 | G11: 4 | H11: Team B | I11: x | J11: x | K11: x | L11: x
A12: FC3 | B12: 1 | C12: Mechanical performance | D12: 3D design | E12: 4 | F12: 3 | G12: 6 | H12: Team B | K12: x | L12: x | M12: x | N12: x
A13: FC3 | B13: 1 | C13: Mechanical performance | D13: LS dyna simulation | E13: 5 | F13: 5 | G13: 9 | H13: Team B | M13: x | N13: x | O13: x | P13: x | Q13: x
A14: FC3 | B14: 1 | C14: Mechanical performance | D14: Optimize parameters | E14: 4 | F14: 8 | G14: 11 | H14: Team B | P14: x | Q14: x | R14: x | S14: x
A15: FC3 | B15: 1 | C15: Mechanical performance | D15: Model scale test | E15: 3 | F15: 10 | G15: 12 | H15: Team B | R15: x | S15: x | T15: x
A16: FC3 | B16: 1 | C16: Mechanical performance | D16: Fatigue | E16: =IF(ISBLANK(F16),,G16-F16+1) -> 3 | F16: 11 | G16: 13 | H16: Team B | S16: x | T16: x | U16: x
A17: FC3 | B17: 1 | C17: Mechanical performance | D17: Tensile strength | E17: =IF(ISBLANK(F17),,G17-F17+1) -> 2 | F17: 12 | G17: 13 | H17: Team B | T17: x | U17: x
A18: FC3 | B18: 1 | C18: Mechanical performance | D18: Shear strength | E18: =IF(ISBLANK(F18),,G18-F18+1) -> 2 | F18: 13 | G18: 14 | H18: Team B | U18: x | V18: x
A19: FC3 | B19: 1 | C19: Mechanical performance | D19: Compression strength | E19: =IF(ISBLANK(F19),,G19-F19+1) -> 2 | F19: 14 | G19: 15 | H19: Team B | V19: x | W19: x
A20: FC3 | B20: 1 | C20: Mechanical performance | D20: Full scale prototype testing | E20: =IF(ISBLANK(F20),,G20-F20+1) -> 4 | F20: 15 | G20: 18 | H20: Team B | W20: x | X20: x | Y20: x | Z20: x
A21: FC3 | B21: 1 | C21: Mechanical performance | D21: Source a new hinge | E21: =IF(ISBLANK(F21),,G21-F21+1) -> 1 | F21: 18 | G21: 18 | H21: Team B | Z21: x
E22: =IF(ISBLANK(F22),,G22-F22+1)
A23: FC10 | B23: 1 | C23: PV attachment | D23: Investigate glue | E23: =IF(ISBLANK(F23),,G23-F23+1) -> 4 | F23: 1 | G23: 4 | H23: Team C | I23: x | J23: x | K23: x | L23: x
A24: FC10 | B24: 1 | C24: PV attachment | D24: Investigate weld | E24: =IF(ISBLANK(F24),,G24-F24+1) -> 4 | F24: 4 | G24: 7 | H24: Team C | L24: x | M24: x | N24: x | O24: x
A25: FC10 | B25: 1 | C25: PV attachment | D25: Investigate roller hemming/seaming | E25: =IF(ISBLANK(F25),,G25-F25+1) -> 4 | F25: 7 | G25: 10 | H25: Team C | O25: x | P25: x | Q25: x | R25: x
A26: FC10 | B26: 1 | C26: PV attachment | D26: Investigate clinching | E26: =IF(ISBLANK(F26),,G26-F26+1) -> 4 | F26: 10 | G26: 13 | H26: Team C | R26: x | S26: x | T26: x | U26: x
A27: FC10 | B27: 1 | C27: PV attachment | D27: Investigate bolting | E27: =IF(ISBLANK(F27),,G27-F27+1) -> 4 | F27: 13 | G27: 16 | H27: Team C | U27: x | V27: x | W27: x | X27: x
A28: FC10 | B28: 1 | C28: PV attachment | D28: Final adjustments and review | E28: =IF(ISBLANK(F28),,G28-F28+1) -> 4 | F28: 16 | G28: 19 | H28: Team C | X28: x | Y28: x | Z28: x | AA28: x
E29: =IF(ISBLANK(F29),,G29-F29+1)
A30: FC2 | B30: 2 | C30: Water protection | D30: Marine PU foam inside the float itself | E30: =IF(ISBLANK(F30),,G30-F30+1) -> 3 | F30: 16 | G30: 18 | H30: Team A | X30: x | Y30: x | Z30: x
A31: FC2 | B31: 2 | C31: Water protection | D31: Heighten the PV above the waterline | E31: =IF(ISBLANK(F31),,G31-F31+1) -> 3 | F31: 18 | G31: 20 | H31: Team A | Z31: x | AA31: x | AB31: x
A32: FC2 | B32: 2 | C32: Water protection | D32: Protect the backside of the PV and the junction box with Foam | E32: =IF(ISBLANK(F32),,G32-F32+1) -> 2 | F32: 20 | G32: 21 | H32: Team A | AB32: x | AC32: x
A33: FC2 | B33: 2 | C33: Water protection | D33: Extra protecting box with PM | E33: =IF(ISBLANK(F33),,G33-F33+1) -> 2 | F33: 21 | G33: 22 | H33: Team A | AC33: x | AD33: x
A34: FC2 | B34: 2 | C34: Water protection | D34: Enhance the protection of the PV edge | E34: =IF(ISBLANK(F34),,G34-F34+1) -> 2 | F34: 22 | G34: 23 | H34: Team A | AD34: x | AE34: x
A35: FC2 | B35: 2 | C35: Water protection | D35: Protect the cables going in and out of the float | E35: =IF(ISBLANK(F35),,G35-F35+1) -> 2 | F35: 23 | G35: 24 | H35: Team A | AE35: x | AF35: x
A36: FC2 | B36: 2 | C36: Water protection | D36: MC4 connectors must be protected | E36: =IF(ISBLANK(F36),,G36-F36+1) -> 3 | F36: 24 | G36: 26 | H36: Team A | AF36: x | AG36: x | AH36: x
E37: =IF(ISBLANK(F37),,G37-F37+1)
A38: FS1 | B38: 2 | C38: Walkability | D38: Choose a glass/glass PV | E38: =IF(ISBLANK(F38),,G38-F38+1) -> 1 | F38: 13 | G38: 13 | H38: Team A | U38: x
A39: FS1 | B39: 2 | C39: Walkability | D39: Ensure the PV is supported on its backside | E39: =IF(ISBLANK(F39),,G39-F39+1) -> 2 | F39: 13 | G39: 14 | H39: Team A | U39: x | V39: x
A40: FS1 | B40: 2 | C40: Walkability | D40: Study/test the buoyancy balance of a float | E40: =IF(ISBLANK(F40),,G40-F40+1) -> 2 | F40: 14 | G40: 15 | H40: Team A | V40: x | W40: x
E41: =IF(ISBLANK(F41),,G41-F41+1)
...

Sheet Design
A1: This page describe various aspects of the solution that touches one or more functions of the system
A2: Each aspect can have multiple options that should be investigated.
A3: Each combination of options for each aspect may be an eligible solution and should be assessed.
A5: Frame / float relation | B5: Float | C5: Sheet shape | D5: Dimples joining | E5: Infill | F5: Infill around junction box | G5: Infill or frame air pockets | H5: Attachment point to mooring system
A6: 1 Frame integrated float | B6: 1 Single alu sheet | C6: None | D6: Glue | E6: 1 Polystyrene | F6: Infill split in to with gap | G6: PU foam | H6: 3 Half hinge
A7: 2 Separate frame and float | B7: 2 Double alu sheet | C7: 1 Through | D7: Friction stir welding | E7: Honeycomb | F7: 1 Infill exact cutout | G7: Potting | H7: Full hinge
B8: Plastic | C8: Through and dimples | D8: Capacitance discharge welding | E8: 1 Air | F8: 2 None | G8: 3 Air | H8: intermediate float
C9: 1 Dimples | D9: 3 None | E9: 1 PU foam | G9: Glue | H9: inflatable buoy thing
A14: Panel underside joining | B14: Panel tilt | C14: MC4 cables | D14: Hinge / frame relation | E14: Hinge reinforcement | G14: Hinge edge coverage | H14: Hinge material
A15: 1 Glue | B15: 3 Slight tilt | C15: 1 Through frame | D15: Wrap around sheet edge | E15: 2 None | G15: 1 Along full edge of float | H15: 3 PU
A16: Heatable laminate | B16: Flat | C16: 2 Under frame | D16: 1 Wrap around panel frame | E16: 1 PVC pipe | G16: Along partial edge of float | H16: PP rope
A17: 2 None | C17: Junction box on top | D17: 2 Brackets joined to float | E17: Corner hinge | G17: 2 Individual hinges
D18: Brackets joined to panel frame | E18: 1 Rope
A22: Hinge buoyancy | B22: Grounding type | C22: Grounding cabling | D22: Stream protection type | E22: Stream protection fastening | F22: Matrix edge protection | G22: Dummy float | H22: Water drainage
A23: None | B23: 3 Frame connected | C23: 3 Alongside MC4s | D23: Cylindrical width wise buoy | E23: 1 Via hinge system | F23: 1 Dummy float | G23: Plastic | H23: Plastic clip
A24: 1 Some | B24: To water | C24: Separate path | D24: Cylindrical length wise buoy | E24: To the float | F24: 1 Cylindrical | G24: 3 Same as float but with alu treadplates | H24: 3 Metal clip
C25: None | D25: 3 Bow shaped buoy | E25: To the frame | F25: 1 Same as stream protection | H25: None
D26: Bow shape, non buoyant | E26: 1 None (part of mooring) | F26: 1 Barge
D27: None
A31: Stacking | B31: Deployment | C31: Hinge UV protection | D31: Float extends panel area
A32: Unassembled PV | B32: Accordion | C32: Sock around the hinge | D32: 2 Yes
A33: 1 Vertical | B33: 3 One by one | C33: 3 Built into material | D33: 1 No
A34: 1 Horizontal | B34: 2 row by row
A35: tilted
A36: 2 stories

Sheet Design considerations
A1: Double float, no dimples, through, slight tilt, infill, float extends panel area
A2: Pros | B2: Cons
A3: Better hydrodynamic | B3: more expensive
A4: Better electrical protection, less splash | B4: possibly more steps
A5: Better against freezing water | B5: lesser energy density
A6: More robust | B6: higher energy footprint
A7: Easier to exchange solar panels | B7: heavier - problem in production
A8: Less complex due to separable components | B8: heavier - installation/deployement
A9: Facilitates edge clamps or alu lift profiles | B9: Volumous shipping
A10: Easier to make a water and air-tight construction, ex FSW first then inflate | B10: Worse heat conductivity
A11: More design freedom to shape and reshape
A12: More space on the float
A13: Higher buoyancy
A15: Single float, dimples, no through, slight tilt, no infill, float does not extend
A16: Pros | B16: Cons
A17: Very little material usage | B17: Hetreogenous heat conduction (?)
A18: Lightweight- better for production | B18: Harder to protect against electrical faults
A19: lightweight - installation/deployment | B19: Less robust
A20: More heat conductive | B20: Less buoyancy
A21: Price | B21: Less options for changing panel in the field
A22: Less volumous shipping | B22: Worse regarding warranty
A23: Enables bespoke frame/hinge integration
A26: Hinge attached to float, single hinge, brackety, no reinforcement, PU
A27: Pros | B27: Cons
A28: Based on current experience and work | B28: Single point of force distribution
A29: Simple hinge - no reinforcement | B29: Many different components - stuff lost at site, stuff that can break, logistics, production time
A30: Flexibility, can change hinges easily | B30: Might allow whipping actions
A31: Low UV exposure | B31: More challenging to withstand compression
A32: Cheap (casting, metal brackets) | B32: Fastened on a thin part of the floating unit rather than a thick part
A33: Brackets enable force distribution on the float
A34: Many or few - flexible
A35: Can avoid force on the float
A38: Hinge attached to panel, full side of float hinge, no brackets, reinforced, PU
A39: Pros | B39: Cons
A40: Homogenous distribution of force | B40: Challenging tooling x2
A41: Disallows splashing | B41: Force goes directly into the panel
A42: Offers buoyancy | B42: Does not handle twisting well
A43: Prevents compression effectively | B43: Impossible to change a float or PV
A44: Skip fastening of alu sheet to panel frame (potentially) | B44: Worse regarding warranty
A45: Protects from water intgress via the MC4 cable

Sheet Design Per
A1: Frame / float relation | B1: Float | C1: Sheet shape | D1: Dimples joining | E1: Infill | F1: Infill around junction box | G1: Infill or frame air pockets | H1: Attachment point to mooring system
H2: Half hinge
A3: Separate frame and float | B3: Double alu sheet | C3: Through
G4: Air
D5: None | E5: PU foam
A10: Panel underside joining | B10: Panel tilt | C10: MC4 cables | D10: Hinge / frame relation | E10: Hinge reinforcement | F10: Roped hinges | G10: Hinge edge coverage | H10: Hinge material
B11: Slight tilt | D11: Wrap around sheet edge | E11: None | F11: Rope | H11: PU
C12: Under frame | F12: No rope | H12: PP rope
A13: None | G13: Individual hinges
D14: Brackets joined to frame | E14: Rope
A18: Hinge buoyancy | B18: Grounding type | C18: Grounding cabling | D18: Stream protection type | E18: Stream protection fastening | F18: Matrix edge protection | G18: Dummy float | H18: Water drainage
A19: None | B19: Frame connected | C19: Alongside MC4s | D19: Cylindrical buoy | E19: Via hinge system | F19: Dummy float | H19: Plastic clip
D20: Bow shaped buoy | E20: To the float | F20: Cylindrical | G20: Same as float but with alu treadplates | H20: Metal clip
D21: Bow shape, non buoyant | E21: To the frame | F21: Same as stream protection | H21: None
D22: None | E22: None (part of mooring) | F22: Barge
A27: Stacking | B27: Deployment | C27: Hinge UV protection
C28: Sock around the hinge
B29: One by one | C29: Built into material
A30: Horizontal | B30: Same as rest of FPV
A32: 2 stories

Sheet Design Guillaume
D2: Replace with : edge joining = clinch
A5: Frame / float relation | B5: Float | C5: Sheet shape | D5: Dimples joining | E5: Infill | F5: Infill around junction box | G5: Infill or frame air pockets | H5: Attachment point to mooring system
D6: Glue | E6: Polystyrene | H6: Half hinge
A7: Separate frame and float | B7: Double alu sheet | C7: Through | D7: Friction stir welding | F7: Infill exact cutout
B8: Plastic | D8: Capacitance discharge welding | G8: Air
A14: Panel underside joining | B14: Panel tilt | C14: MC4 cables | D14: Hinge / frame relation | E14: Hinge reinforcement | G14: Hinge edge coverage | H14: Hinge material
B15: Slight tilt | E15: None | H15: PU
A17: None | C17: Junction box on top | D17: Brackets joined to float | G17: Individual hinges
A22: Hinge buoyancy | B22: Grounding type | C22: Grounding cabling | D22: Stream protection type | E22: Stream protection fastening | F22: Matrix edge protection | G22: Dummy float | H22: Water drainage
A23: None | B23: Frame connected | C23: Alongside MC4s | E23: Via hinge system | F23: Dummy float
D24: Bow shaped buoy | G24: Same as float but with alu treadplates | H24: Metal clip
E26: None (part of mooring)
A31: Stacking | B31: Deployment | C31: Hinge UV protection
B33: One by one | C33: Built into material
A34: Horizontal

Sheet Design - Eirik
A1: Frame / float relation | B1: Float | C1: Sheet shape | D1: Dimples joining | E1: Infill | F1: Infill around junction box | G1: Infill or frame air pockets | H1: Attachment point to mooring system
A2: Frame integrated float | B2: Single alu sheet | G2: PU foam | H2: Half hinge
E4: Air | F4: None
C5: Dimples | D5: None
A10: Panel underside joining | B10: Panel tilt | C10: MC4 cables | D10: Hinge / frame relation | E10: Hinge reinforcement | F10: Roped hinges | G10: Hinge edge coverage | H10: Hinge material
A11: Glue | B11: Slight tilt | C11: Through frame | F11: Rope | G11: Along full edge of float | H11: PU
D12: Wrap around panel frame | E12: PVC pipe
E14: Rope
A18: Hinge buoyancy | B18: Grounding type | C18: Grounding cabling | D18: Stream protection type | E18: Stream protection fastening | F18: Matrix edge protection | G18: Dummy float | H18: Water drainage
B19: Frame connected | C19: Alongside MC4s | E19: Via hinge system
A20: Some | D20: Bow shaped buoy | G20: Same as float but with alu treadplates | H20: Metal clip
F21: Same as stream protection
A27: Stacking | B27: Deployment | C27: Hinge UV protection
A29: Vertical | B29: One by one | C29: Built into material
B30: Same as rest of FPV

Sheet Tasks
A1: Create LS Dyna simulations for hinge. Must be able to take a parameterized cad model (freecad is best) and create a set of output parameters and a score from 0 to 1.
A2: Calculate hinge with octopatch for Surewave
A3: Calculate hinge with oring design
A4: Create fatigue tests for any hinge. LS Dyna? Another tool? IFE?
A5: Create hinge sample for physical testing by Sintef in chinese material
A6: Create miniature of current octopatch design for wave tank testing
A7: Test fluid forming pressing DIY like punch die
A8: Fluid forming pressing DIY from tip
A9: Double sheet fluid forming pressing DIY
A10: Test buoyancy of miniature octopatch with float
A11: Decide on how to get cable through frame in a water-tight manner
A12: Get quotes for honeycomb and polystyrene
... A15: Research connection method for flat aluminum om alu frame

Sheet FP1
A1: Function | B1: Criteria | C1: HOW
A2: Produces power | B2: Performance ratio (how much kWh per kWp), power density (kWp/sqm), soiling degree, cooling effect | C2: Sourcing a high kW output PV panel
C3: Sourcing a glass/glass PV panel for easy cleaning
C4: Sourcing a PV panel with high quality level
C5: Decide of an angle towards the sun

Sheet FP2
A1: Function | B1: Criteria | C1: How
A2: Certiication | B2: Certification not broken by modification/assembly | C2: Clear out with supplier what is posible to touch before breaking certification
C3: Supply a PV panel that is certified
C4: Investagate the certification specification (IEC, and UL) to see if there are voiding conditions

Sheet FC1
A1: Function | B1: Criteria | C1: How
A2: Floats on water | B2: Sufficient Buoyancy of the float / panel / hinges | C2: Single unit buoyancy
C3: Float
C4: floating hinge
C5: Using the PV+frame as a float
C6: 1 hydroformed trofe, 2 HF trofes, with different infils,
C7: Multiple unit buoyancy
C8: Strucutral integraity of the assembled matrix
C9: Saussage on the matrix edge

Sheet FC2
A1: Function | B1: Criteria | C1: How
A2: Is water tight | B2: Float must be water tight. minimize the degradation ratio and fault probability PV & electronics must be protected | C2: Marine PU foam inside the float it self
C3: Heighten the PV above the water line
C4: Protect the backside of the PV and the junction box with Foam
C5: Extra protecting box with PM
C6: Enhance the protection of the PV edge
C7: Protect the Cables going in and out of the float
C8: MC4 connectors must be protected

Sheet FC3
A1: Function | B1: Criteria | C1: How
A2: Is mechanically attached | B2: Tensile strength, shear strength, compression strength, fatigue strength safety value pass. | C2: Sketch
C3: 3D design
C4: LS dyna simu
C5: optimze parameters
C6: Model scale test
C7: Fatigue
C8: Tensile str | D8: Lab testing by SINTEF
C9: Shear str
C10: compression str
C11: Full scale prototype testing
C12: Source a new hinge

Sheet FC4
A1: Function | B1: Criteria | C1: How
A2: Submarining | B2: resist 3m/s stream | C2: Design a stream breaking bow potentially buoyant
C3: Simulate "
C4: Parameter optimization
C5: Scale model test
C6: Source a product out of the shelve

Sheet FC5
A1: Function | B1: Criteria | C1: How
A2: Interchangeability | B2: Keep design open to different standard size | C2: Every 3D design should be done with regards to standard size
C3: Assess the PV on the market (EU, CN and US)
C4: Find a common denominator to work with

Sheet FC6
A1: Function | B1: Criteria | C1: How / Sub fonction
A2: Resists high wind | B2: profile low and no wind traps | C2: Avoid lift
C3: Safety factor for wind induced load
C4: CFD wind software

Sheet FC7
A1: Function | B1: Criteria | C1: How
A2: Resists waves | B2: linked to the hinges and the strucutral integrity of the float | C2: Work with MARIN (From Surewave) to evaluate the new loads on a matrix of different sizes
B3: safety factor for the hinge performances | C3: Apply those loads to a simulation and check that our hinge system validates the safety factor
B4: Resist wave up to 1.5 Hs | C4: Possibly an external consultancy

Sheet FC8
A1: Function | B1: Criteria | C1: How
A2: Cost efficiency | B2: As cheap or cheaper than competitors CAPEX wise (now 250€/kWp) | C2: Cheap PV compared to kWp output
C3: Cheap float
C4: Simplest assembly
C5: Number of components should be low
C6: Number of assembly steps should be low
C7: Cost of extra component should be low
C8: Keep frakt lowest
C9: Cheap infrastructure for prod

Sheet FC9
A1: Function | B1: Criteria | C1: How
A2: Grounding system | B2: Must resist corrosion and constant movement (fatigue) | C2: develop and reinforce the mainnheim system
C3: Attachment
C4: Guide over the FPV

Sheet FC10
A1: Function | B1: Criteria | C1: How
A2: PV attachment | B2: Ease of operation | C2: Investigate glue
B3: Infrastrucutre costs | C3: Investigate weld
B4: Components costs | C4: Investigate roller hemming/seaming
B5: Durability | C5: Investigate clinching
B6: water protection | C6: Investigate bolting

Sheet FC11
A1: Function | B1: Criteria | C1: How
A2: Mooring | B2: System must remain in place safely | C2: Design a mooring system for stream water
C3: Design a mooring system for nearshore/offshore water
C4: Design a mooring system for still water

Sheet FC12
A1: Function | B1: Criteria | C1: How
A2: Internal pressure control | B2: No overpressure | C2: Exhaust hole in float
B3: No cavity | C3: QA on production

Sheet FS1
A1: Function | B1: Criteria | C1: How
A2: Can walk on it | B2: Avoid microcrack when walking on it and float matrix must be stable | C2: Chose a glass/glass PV
C3: Ensure the PV is supported on its backside
C4: Study/test the buoyancy balance of a float

Sheet FS2
A1: Function | B1: Criteria | C1: How / Sub fonction
A2: Manufacturability | B2: Must be possible to assemble in Askim | C2: Processes compatible with mass production
B3: should be exportable to the US. Objective: 90 to 900 floats per weeks for 2 people | C3: Processes compatible with organic production

Sheet FS3
A1: Function | B1: Criteria | C1: How
A2: Fast to install | B2: Plug and play electrically, | C2: Use standard connectors
B3: Objective: 20 kW installed per Man/hour, | C3: Ensure ease of handling
B4: Light FPV carried by 2 ppl | C4: Ensure personnel safety
B5: No tools | C5: Ensure equipment safety

Sheet Roadmap_old
A1: Product v2 development timeline
A3: PROJECT TITLE | F3: Product B development | G3: COMPANY NAME | N3: Sunlit Sea
A4: PROJECT MANAGER | F4: Eirik Larsen | G4: DATE | N4: 45533
G7: PHASE ONE: Conception | V7: PHASE TWO: Simulation | AK7: PHASE THREE: Prototyping | AZ7: PHASE FOUR: Final test
G8: WEEK 1 | L8: WEEK 2 | Q8: WEEK 3 | V8: WEEK 4 | AA8: WEEK 5 | AF8: WEEK 6 | AK8: WEEK 7 | AP8: WEEK 8 | AU8: WEEK 9 | AZ8: WEEK 10 | BE8: WEEK 11 | BJ8: WEEK 12
A9: REF NUMBER | B9: Priority | C9: Function | D9: Task | E9: Duration (person-weeks) | F9: TASK OWNER
A10: ='Function - criteria - Solution'!A2 -> FP1 | B10: ='Function - criteria - Solution'!D2 -> 3 | C10: ='Function - criteria - Solution'!B2 -> Power production | E10: 4
D11: ='FP1'!C2 -> Sourcing a high kW output PV panel
D12: ='FP1'!C3 -> Sourcing a glass/glass PV panel for easy cleaning
D13: ='FP1'!C4 -> Sourcing a PV panel with high quality level
D14: ='FP1'!C5 -> Decide of an angle towards the sun
A16: ='Function - criteria - Solution'!A3 -> FP2 | B16: ='Function - criteria - Solution'!D3 -> 2 | C16: ='Function - criteria - Solution'!B3 -> Certification | E16: 1
D17: ='FP2'!C2 -> Clear out with supplier what is posible to touch before breaking certification
D18: ='FP2'!C3 -> Supply a PV panel that is certified
D19: ='FP2'!C4 -> Investagate the certification specification (IEC, and UL) to see if there are voiding conditions
D20: ='FP2'!C5
A21: ='Function - criteria - Solution'!A4 -> FC1 | B21: ='Function - criteria - Solution'!D4 -> 1 | C21: ='Function - criteria - Solution'!B4 -> Buoyancy | E21: 12
D22: ='FC1'!C2 -> Single unit buoyancy
D23: ='FC1'!C3 -> Float
D24: ='FC1'!C4 -> floating hinge
D25: ='FC1'!C5 -> Using the PV+frame as a float
D26: ='FC1'!C6 -> 1 hydroformed trofe, 2 HF trofes, with different infils,
D27: ='FC1'!C7 -> Multiple unit buoyancy
D28: ='FC1'!C8 -> Strucutral integraity of the assembled matrix
D29: ='FC1'!C9 -> Saussage on the matrix edge
A31: ='Function - criteria - Solution'!A5 -> FC2 | B31: ='Function - criteria - Solution'!D5 -> 2 | C31: ='Function - criteria - Solution'!B5 -> Water protection | E31: 12
D32: ='FC2'!C2 -> Marine PU foam inside the float it self
D33: ='FC2'!C3 -> Heighten the PV above the water line
D34: ='FC2'!C4 -> Protect the backside of the PV and the junction box with Foam
D35: ='FC2'!C5 -> Extra protecting box with PM
D36: ='FC2'!C6 -> Enhance the protection of the PV edge
D37: ='FC2'!C7 -> Protect the Cables going in and out of the float
D38: ='FC2'!C8 -> MC4 connectors must be protected
D39: ='FC2'!C9
A40: ='Function - criteria - Solution'!A6 -> FC3 | B40: ='Function - criteria - Solution'!D6 -> 1 | C40: ='Function - criteria - Solution'!B6 -> Mechnical performance | E40: 20
D41: ='FC3'!C2 -> Sketch
D42: ='FC3'!C3 -> 3D design
D43: ='FC3'!C4 -> LS dyna simu
D44: ='FC3'!C5 -> optimze parameters
D45: ='FC3'!C6 -> Model scale test
...
